Workbook

Sheet Cover
B2: MERGER MODEL & ACQUISITION ANALYSIS
B3: Meridian Industrial Supply, Inc. (MIDS) proposed acquisition of Calder Fluid & Flow Systems, Inc. (CFFS)
B4: All figures in $ millions except per-share data. All companies, figures and market data are fictional and were created for this exercise.
B6: TRANSACTION SNAPSHOT
C8: Proposed Structure | E8: 100% stock (switchable to a cash / debt / stock mix)
C9: Exchange Ratio | E9: 1.4000x
C10: Offer Price per Share | E10: =Merger_Model!$E$15 -> 48.3
C11: Premium to Undisturbed Price | E11: =Merger_Model!$E$17 -> 0.27777778
C12: Purchase Equity Value | E12: =Merger_Model!$E$20 -> 2697.84
C13: Purchase Enterprise Value | E13: =Merger_Model!$E$23 -> 2984.2793
C14: Purchase TEV / FY25E EBITDA | E14: =Merger_Model!E27 -> 9.3927607
C15: Run-Rate Cost Synergies by Year 3 | E15: =Synergies!$I$16 -> 95.437822
C16: Combined Year 1 EPS Accretion / (Dilution) | E16: =Merger_Model!$G$135 -> -0.10827477
C17: Combined Year 3 EPS Accretion / (Dilution) | E17: =Merger_Model!$I$135 -> 0.036944412
B20: HOW TO READ THIS MODEL
C22: Colour convention | E22: Blue — hardcoded input or scenario lever. These are the only cells intended to be edited.
E23: Black — a formula calculated on the same tab.
E24: Green — a live link to another tab.
E25: Grey italics — commentary explaining the assumption or methodology (column M on most tabs).
C27: Key levers | E27: Merger_Model E9 — transaction structure: 2 = 100% stock, 1 = cash / debt / stock mix.
E28: Merger_Model E10 / E11 — switch revenue and expense synergies on or off.
E29: Merger_Model E12 — expense synergy realisation factor, the single most important variable in the model.
E30: Merger_Model E14 — exchange ratio, which drives both the price paid and the ownership split.
C32: Acquirer balance sheet (FY30E) | E32: =Acquirer!K147 -> 0
C33: Target balance sheet (FY30E) | E33: =Target!K147 -> 0
C34: Pro-forma opening balance sheet | E34: =Combined_BS!I40 -> 0
C35: Sources less uses of funds | E35: =Merger_Model!E69 -> 0
B37: TAB INDEX
C39: Merger_Model | E39: Deal assumptions, sources & uses, purchase price allocation, combined income statement and cash flow, EPS accretion and sensitivities.
C40: Acquirer | E40: Meridian standalone three-statement operating model, FY24A-FY30E.
C41: Target | E41: Calder standalone three-statement operating model, FY24A-FY30E.
C42: Synergies | E42: Headcount-driven cost synergies, cross-sell revenue synergies, costs to achieve, and the PV of synergies versus the premium paid.
C43: Combined_BS | E43: Purchase-accounting balance sheet combination at the close date.
C44: DCF_IRR | E44: Ten-year unlevered DCF of the target and the acquirer's IRR on the transaction, with sensitivities.
C45: WACC | E45: Peer beta unlevering and re-levering; discount rates for both companies.
C46: Pub_Comps | E46: Trading comparables for the sector.
C47: MA_Comps | E47: Precedent control transactions.
C48: Contrib | E48: Relative contribution analysis and the exchange ratio each metric implies.
C49: Value_Creation | E49: Combined entity valued against larger-cap platform multiples.

Sheet Merger_Model
B2: Merger Model -Meridian Industrial Supply, Inc. (MIDS) / Calder Fluid & Flow Systems, Inc. (CFFS)
B3: ($ in millions, except per-share and per-unit data)
B4: Transaction assumptions, sources & uses, purchase price allocation and the combined income statement, cash flow and credit profile. FY26E is the first full combined year (Combined Year 1).
B5: 1. TRANSACTION ASSUMPTIONS & DEAL SWITCHES | M5: Yellow-shaded cells are the levers a reviewer should drive: deal structure, synergy switches and the realisation factor.
C7: Transaction Close Date | D7: Date | E7: 46022 | F7: (end of FY25E)
C8: Valuation / Analysis Date | D8: Date | E8: 46022
C9: Transaction Type (1 = Cash / Debt / Stock, 2 = 100% Stock) | D9: # | E9: 2 | M9: Master structure switch. 2 = management's proposed all-stock deal. 1 = maximum cash and debt first, with stock plugging the balance.
C10: Include Revenue Synergies? (1 = Yes, 0 = No) | D10: # | E10: 1
C11: Include Expense Synergies? (1 = Yes, 0 = No) | D11: # | E11: 1
C12: Expense Synergy Realisation Factor | D12: % | E12: 1
C14: Exchange Ratio | D14: x | E14: 1.4 | M14: Target holders receive this many Meridian shares per Calder share. Drives both the offer price and the pro-forma ownership split.
C15: Implied Offer Price per Share | D15: $ / sh | E15: =E14*Acquirer!E11 -> 48.3
C16: Target Share Price (Undisturbed) | D16: $ / sh | E16: =Target!$E$11 -> 37.8
C17: Premium Paid | D17: % | E17: =E15/E16-1 -> 0.27777778
C19: Target Diluted Shares @ Offer Price | D19: M sh | E19: =Target!E13+IF(Merger_Model!E15>Target!S16,Target!$R$16-Target!$R$16*Target!$S$16/Merger_Model!E15,0)+Target!R17 -> 55.855901 | M19: Treasury stock method re-run at the OFFER price, not the market price -a higher offer pulls more options into the money and raises the share count being bought.
C20: Purchase Equity Value | D20: $M | E20: =E15*E19 -> 2697.84
C21: (+) Target Total Debt Assumed / Refinanced | D21: $M | E21: =Target!F135 -> 506.7 | M21: Calder's debt is refinanced at close on identical economics, so it is a wash in the accretion analysis but still sits in the purchase enterprise value.
C22: (-) Target Cash Acquired | D22: $M | E22: =-Target!F116 -> -220.26067
C23: Purchase Enterprise Value | D23: $M | E23: =SUM(E20:E22) -> 2984.2793
C25: Purchase TEV / FY25E Revenue | D25: x | E25: =E23/Target!F90 -> 1.1018199
C26: Purchase TEV / FY24A EBITDA | D26: x | E26: =E23/Target!E192 -> 10.558162
C27: Purchase TEV / FY25E EBITDA | D27: x | E27: =E23/Target!F192 -> 9.3927607 | M27: Compare against the trading comps (Pub_Comps) and the precedent transactions (MA_Comps) to judge whether the price is fair.
C28: Purchase Equity Value / FY25E Net Income | D28: x | E28: =E20/Target!F108 -> 15.434651
B30: 2. FINANCING CAPACITY & COST | M30: Sets the ceiling on how much cash and debt the buyer can put into the deal before the stock component has to fill the gap.
C31: Post-Transaction Minimum Cash Balance | D31: $M | E31: 200 | M31: Operating cash the combined business must retain for working-capital seasonality; it cannot be spent on the deal.
C32: Combined Cash at Close (FY25E) | D32: $M | E32: =Acquirer!F116+Target!F116 -> 582.42509
C33: Maximum Cash Available for the Deal | D33: $M | E33: =MAX(E32-E31,0) -> 382.42509
C34: Maximum Combined Debt / EBITDA | D34: x | E34: 4 | M34: Credit-agreement style ceiling. At 4.0x the combined company would sit at the top of the range peers can carry -arguably too far, which is the point of case question 3.
C35: Combined FY25E EBITDA | D35: $M | E35: =Acquirer!F192+Target!F192 -> 953.52712
C36: Existing Combined Debt at Close | D36: $M | E36: =Acquirer!F135+Target!F135 -> 2040.9
C37: Maximum New Debt Available for the Deal | D37: $M | E37: =MAX(E34*E35-E36,0) -> 1773.2085
C38: New Debt - Premium to Acquirer's Cost of Debt | D38: bps | E38: 200
C39: New Debt - Pre-Tax Interest Rate | D39: % | E39: =Acquirer!E75+Merger_Model!E38/10000 -> 0.0775 | M39: Acquisition debt prices wide of the existing capital structure because it is incremental leverage on a larger, less proven credit.
C40: New Debt - Annual Amortisation | D40: % | E40: 0.01
C41: New Debt - Maturity | D41: # yrs | E41: 5
C42: Foregone Interest Rate on Cash Used | D42: % | E42: 0.035 | M42: Cash spent on the deal stops earning interest -a real, if small, cost of the cash component.
C44: Advisory Fee (% of Purchase Equity Value) | D44: % | E44: 0.01
C45: Debt Issuance Fee (% of New Debt) | D45: % | E45: 0.02
C46: Legal, Accounting & Other Fees | D46: $M | E46: 12
B48: 3. CONSIDERATION MIX & THE ACCRETION TEST
...

Sheet Acquirer
B2: Acquirer: Meridian Industrial Supply, Inc. (MIDS) — Standalone Operating Model
B3: ($ in Millions Except Per Share and Per Unit Data)
B4: Meridian is a national distributor of maintenance, repair and operating (MRO) supplies, fasteners, power-transmission components and fluid-handling products, serving industrial, energy and institutional end markets through ~230 branches and four regional DCs.
B5: 1. FINANCIAL PROFILE & CURRENT MARKET VALUATION | D5: Units
C7: Company Name: | D7: Name | E7: Meridian Industrial Supply, Inc.
C8: Ticker: | D8: Name | E8: MIDS
C9: Last Fiscal Year: | D9: Date | E9: 45657
C10: Effective Tax Rate: | D10: % | E10: 0.24 | M10: Blended federal + state rate, held flat. Drives the tax provision in every projected year.
C11: Share Price (Undisturbed) | D11: $ as Stated | E11: 34.5 | M11: Unaffected price one day prior to announcement — the basis for the offer premium.
C13: Basic Shares Outstanding | D13: M sh | E13: 116.4 | P13: Treasury Stock Method:
C14: (+) Net Dilution from Options & RSUs | D14: M sh | E14: =T20 -> 2.3057971 | M14: Treasury stock method — schedule in columns P:S. Options are dilutive only when in the money.
C15: Diluted Shares Outstanding | D15: M sh | E15: =SUM(E13:E14) -> 118.7058 | P15: Name: | R15: Units (M) | S15: Strike | T15: Net Dilution
P16: Options | R16: 3.2 | S16: 21.5 | T16: =IF($E$11>S16,R16-R16*S16/$E$11, 0) -> 1.2057971
C17: Current Equity Value (Market Capitalisation) | D17: $M | E17: =E15*E11 -> 4095.35 | P17: RSUs / Restricted Stock | R17: 1.1 | S17: n/a | T17: =R17 -> 1.1
C18: (-) Cash & Cash Equivalents | D18: $M | E18: =-E116 -> -210.04235
C19: (+) Total Debt & Finance Leases | D19: $M | E19: =E135 -> 1650
C20: (+) Operating Lease Liabilities | D20: $M | M20: Deliberately excluded: Rent is part of SG&A, so, lease is excluded. Treated the same way on Pub_Comps and MA_Comps. | P20: Total Net Dilution | R20: =SUM(R16:R17) -> 4.3 | T20: =SUM(T16:T17) -> 2.3057971
C21: (+) Preferred Stock | D21: $M
C22: (+) Noncontrolling Interests | D22: $M
C23: (-) NOLs & Non-Core Assets | D23: $M | M23: Neither company carries material NOLs or non-core assets; set to zero to keep the bridge clean.
C24: Current Enterprise Value (TEV) | D24: $M | E24: =SUM(E17:E23) -> 5535.3077
C26: TEV / FY24A EBITDA | D26: x | E26: =E24/E192 -> 9.4133691
C27: TEV / FY25E EBITDA | D27: x | E27: =E24/F192 -> 8.7059708
C28: Price / FY24A EPS | D28: x | E28: =E11/E111 -> 13.657464
B32: 2. OPERATING DRIVERS & PROJECTION ASSUMPTIONS | G32: Projected: | M32: Every projected line item is driven from this block of drivers.
E33: =Merger_Model!$E$89 -> 45657 | F33: =Merger_Model!$F$89 -> 46022 | G33: =Merger_Model!$G$89 -> 46387 | H33: =Merger_Model!$H$89 -> 46752 | I33: =Merger_Model!$I$89 -> 47118 | J33: =Merger_Model!$J$89 -> 47483 | K33: =Merger_Model!$K$89 -> 47848
C35: Revenue Growth Rates by Segment:
C36: Fasteners & MRO Consumables | D36: % | E36: n/a | F36: 0.03 | G36: 0.035 | H36: 0.033 | I36: 0.03 | J36: 0.028 | K36: 0.025
C37: Power Transmission & Automation | D37: % | E37: n/a | F37: 0.055 | G37: 0.06 | H37: 0.055 | I37: 0.05 | J37: 0.045 | K37: 0.04
C38: Fluid Handling & Process | D38: % | E38: n/a | F38: 0.035 | G38: 0.045 | H38: 0.042 | I38: 0.038 | J38: 0.035 | K38: 0.03
C39: Safety & Facility Solutions | D39: % | E39: n/a | F39: 0.045 | G39: 0.05 | H39: 0.048 | I39: 0.045 | J39: 0.04 | K39: 0.035
C40: Engineered Services & Solutions | D40: % | E40: n/a | F40: 0.065 | G40: 0.07 | H40: 0.065 | I40: 0.06 | J40: 0.05 | K40: 0.045
C42: Cost of Sales % of Revenue | D42: % | E42: =-E91/E90 -> 0.735 | F42: 0.734 | G42: 0.732 | H42: 0.73 | I42: 0.729 | J42: 0.728 | K42: 0.728 | M42: Gross-margin improves due to private-label penetration and also due to normalisation of freight and input costs
C44: Total Employees | D44: # | E44: 14200 | F44: 14150 | G44: 14450 | H44: 14700 | I44: 14900 | J44: 15050 | K44: 15150 | M44: Head-count is a core SG&A Driver. It is also the lever pulled in cost-synergy schedule
C45: Revenue per Employee | D45: $ | E45: =E90*1000000/E44 -> 435563.38 | F45: =F90*1000000/F44 -> 455517.67 | G45: =G90*1000000/G44 -> 467549.27 | H45: =H90*1000000/H44 -> 480339.35 | I45: =I90*1000000/I44 -> 493504.76 | J45: =J90*1000000/J44 -> 506818.21 | K45: =K90*1000000/K44 -> 520108.91
C46: SG&A Spending per Employee | D46: $ | E46: =-E95*1000000/E44 -> 74014 | F46: =E46*(1+F47) -> 76234.42 | G46: =F46*(1+G47) -> 78521.453 | H46: =G46*(1+H47) -> 80877.096 | I46: =H46*(1+I47) -> 83141.655 | J46: =I46*(1+J47) -> 85469.621 | K46: =J46*(1+K47) -> 87606.362 | M46: SG&A = Employees x cost per employee. This way we can directly link workforce reduction to dollars
C47: Growth Rate | D47: % | F47: 0.03 | G47: 0.03 | H47: 0.03 | I47: 0.028 | J47: 0.028 | K47: 0.025
C49: Depreciation % of Revenue | D49: % | E49: =-E96/E90 -> 0.0115 | F49: 0.0116 | G49: 0.0118 | H49: 0.0119 | I49: 0.012 | J49: 0.012 | K49: 0.012
C50: Amortisation of Intangibles % of Revenue | D50: % | E50: =-E97/E90 -> 0.0042 | F50: 0.0042 | G50: 0.0041 | H50: 0.0039 | I50: 0.0037 | J50: 0.0035 | K50: 0.0033 | M50: Existing tangibles amortise over time, so this % goes down over the period
C51: Legacy Merger & Integration Costs | D51: $M | E51: 0 | F51: 0 | G51: 0 | H51: 0 | I51: 0 | J51: 0 | K51: 0
...

Sheet Target
B2: Target: Calder Fluid & Flow Systems, Inc. (CFFS) — Standalone Operating Model
B3: ($ in Millions Except Per Share and Per Unit Data)
B4: Calder designs and distributes flow-control equipment — valves and actuation, engineered pump packages, skid assemblies and instrumentation — with a growing aftermarket and field service arm. Higher gross margin and more engineered content than a pure-play distributor.
B5: 1. FINANCIAL PROFILE & CURRENT MARKET VALUATION | D5: Units
C7: Company Name: | D7: Name | E7: Calder Fluid & Flow Systems, Inc.
C8: Ticker: | D8: Name | E8: CFFS
C9: Last Fiscal Year: | D9: Date | E9: 45657
C10: Effective Tax Rate: | D10: % | E10: 0.245 | M10: Blended federal + state rate, held flat. Drives the tax provision in every projected year.
C11: Share Price (Undisturbed) | D11: $ as Stated | E11: 37.8 | M11: Unaffected price one day prior to announcement — the basis for the offer premium.
C13: Basic Shares Outstanding | D13: M sh | E13: 54.2 | P13: Treasury Stock Method:
C14: (+) Net Dilution from Options & RSUs | D14: M sh | E14: =T20 -> 1.3936508 | M14: Treasury stock method — schedule in columns P:S. Options are dilutive only when in the money.
C15: Diluted Shares Outstanding | D15: M sh | E15: =SUM(E13:E14) -> 55.593651 | P15: Name: | R15: Units (M) | S15: Strike | T15: Net Dilution
P16: Options | R16: 1.9 | S16: 24 | T16: =IF($E$11>S16,R16-R16*S16/$E$11, 0) -> 0.69365079
C17: Current Equity Value (Market Capitalisation) | D17: $M | E17: =E15*E11 -> 2101.44 | P17: RSUs / Restricted Stock | R17: 0.7 | S17: n/a | T17: =R17 -> 0.7
C18: (-) Cash & Cash Equivalents | D18: $M | E18: =-E116 -> -118.00792
C19: (+) Total Debt & Finance Leases | D19: $M | E19: =E135 -> 545
C20: (+) Operating Lease Liabilities | D20: $M | E20: 0 | M20: Deliberately excluded: Rent is part of SG&A, so, lease is excluded. Treated the same way on Pub_Comps and MA_Comps. | P20: Total Net Dilution | R20: =SUM(R16:R17) -> 2.6 | T20: =SUM(T16:T17) -> 1.3936508
C21: (+) Preferred Stock | D21: $M | E21: 0
C22: (+) Noncontrolling Interests | D22: $M | E22: 0
C23: (-) NOLs & Non-Core Assets | D23: $M | E23: 0 | M23: Neither company carries material NOLs or non-core assets; set to zero to keep the bridge clean.
C24: Current Enterprise Value (TEV) | D24: $M | E24: =SUM(E17:E23) -> 2528.4321
C26: TEV / FY24A EBITDA | D26: x | E26: =E24/E192 -> 8.945408
C27: TEV / FY25E EBITDA | D27: x | E27: =E24/F192 -> 7.9580209
C28: Price / FY24A EPS | D28: x | E28: =E11/E111 -> 14.447803
B32: 2. OPERATING DRIVERS & PROJECTION ASSUMPTIONS | G32: Projected: | M32: Every projected line item is driven from this block of drivers.
E33: =Merger_Model!$E$89 -> 45657 | F33: =Merger_Model!$F$89 -> 46022 | G33: =Merger_Model!$G$89 -> 46387 | H33: =Merger_Model!$H$89 -> 46752 | I33: =Merger_Model!$I$89 -> 47118 | J33: =Merger_Model!$J$89 -> 47483 | K33: =Merger_Model!$K$89 -> 47848
C35: Revenue Growth Rates by Segment:
C36: Valves & Actuation | D36: % | E36: n/a | F36: 0.045 | G36: 0.05 | H36: 0.048 | I36: 0.045 | J36: 0.04 | K36: 0.035
C37: Pumps & Fluid Handling | D37: % | E37: n/a | F37: 0.05 | G37: 0.055 | H37: 0.052 | I37: 0.048 | J37: 0.045 | K37: 0.04
C38: Engineered Assemblies | D38: % | E38: n/a | F38: 0.03 | G38: 0.04 | H38: 0.04 | I38: 0.038 | J38: 0.035 | K38: 0.03
C39: Instrumentation & Controls | D39: % | E39: n/a | F39: 0.055 | G39: 0.06 | H39: 0.055 | I39: 0.052 | J39: 0.048 | K39: 0.045
C40: Aftermarket & Field Services | D40: % | E40: n/a | F40: 0.065 | G40: 0.07 | H40: 0.065 | I40: 0.06 | J40: 0.055 | K40: 0.05
C42: Cost of Sales % of Revenue | D42: % | E42: =-E91/E90 -> 0.71 | F42: 0.708 | G42: 0.705 | H42: 0.703 | I42: 0.701 | J42: 0.7 | K42: 0.7 | M42: Gross-margin improves due to private-label penetration and also due to normalisation of freight and input costs
C44: Total Employees | D44: # | E44: 6300 | F44: 6280 | G44: 6420 | H44: 6540 | I44: 6650 | J44: 6740 | K44: 6820 | M44: Head-count is a core SG&A Driver. It is also the lever pulled in cost-synergy schedule
C45: Revenue per Employee | D45: $ | E45: =E90*1000000/E44 -> 410317.46 | F45: =F90*1000000/F44 -> 431289.81 | G45: =G90*1000000/G44 -> 444552.1 | H45: =H90*1000000/H44 -> 458725.82 | I45: =I90*1000000/I44 -> 472682.54 | J45: =J90*1000000/J44 -> 486767.39 | K45: =K90*1000000/K44 -> 499763.72
C46: SG&A Spending per Employee | D46: $ | E46: =-E95*1000000/E44 -> 72222 | F46: =E46*(1+F47) -> 74388.66 | G46: =F46*(1+G47) -> 76620.32 | H46: =G46*(1+H47) -> 78918.929 | I46: =H46*(1+I47) -> 81128.659 | J46: =I46*(1+J47) -> 83400.262 | K46: =J46*(1+K47) -> 85485.268 | M46: SG&A = Employees x cost per employee. This way we can directly link workforce reduction to dollars
C47: Growth Rate | D47: % | F47: 0.03 | G47: 0.03 | H47: 0.03 | I47: 0.028 | J47: 0.028 | K47: 0.025
C49: Depreciation % of Revenue | D49: % | E49: =-E96/E90 -> 0.0155 | F49: 0.0156 | G49: 0.0157 | H49: 0.0157 | I49: 0.0156 | J49: 0.0155 | K49: 0.0155
C50: Amortisation of Intangibles % of Revenue | D50: % | E50: =-E97/E90 -> 0.0062 | F50: 0.0061 | G50: 0.0059 | H50: 0.0057 | I50: 0.0055 | J50: 0.0053 | K50: 0.0051 | M50: Existing tangibles amortise over time, so this % goes down over the period
C51: Legacy Merger & Integration Costs | D51: $M | E51: 0 | F51: 6 | G51: 3 | H51: 0 | I51: 0 | J51: 0 | K51: 0 | M51: This is integration costs of arlier acquistions. Expect it to complete by FY27
...

Sheet Synergies
B2: Synergy Estimates - Meridian Industrial Supply, Inc. / Calder Fluid & Flow Systems, Inc.
B3: ($ in millions, except per-share and per-unit data)
B4: Cost synergies are built bottom-up from headcount; revenue synergies from cross-selling Calder's flow-control lines through Meridian's branch network. Both are switched on/off from the Merger_Model tab.
B5: 1. EXPENSE (COST) SYNERGIES — BUILT FROM HEADCOUNT | M5: The single most scrutinised number in the deal. Building it off a named reduction in force makes it defensible rather than a plug.
D6: ($ in millions) | G6: =Merger_Model!$G$89 -> 46387 | H6: =Merger_Model!$H$89 -> 46752 | I6: =Merger_Model!$I$89 -> 47118 | J6: =Merger_Model!$J$89 -> 47483 | K6: =Merger_Model!$K$89 -> 47848
C8: Target - Reduction in Force | D8: # people | G8: 340 | H8: 440 | I8: 500 | J8: 500 | K8: 500 | M8: Duplicate corporate, finance, IT and branch-administration roles at Calder. Ramps over three years, then holds flat.
C9: Target - SG&A Cost per Employee | D9: $ | G9: =Target!G46 -> 76620.32 | H9: =Target!H46 -> 78918.929 | I9: =Target!I46 -> 81128.659 | J9: =Target!J46 -> 83400.262 | K9: =Target!K46 -> 85485.268
C10: Target - Cost Savings | D10: $M | G10: =G8*G9/1000000 -> 26.050909 | H10: =H8*H9/1000000 -> 34.724329 | I10: =I8*I9/1000000 -> 40.56433 | J10: =J8*J9/1000000 -> 41.700131 | K10: =K8*K9/1000000 -> 42.742634
C12: Acquirer - Reduction in Force | D12: # people | G12: 400 | H12: 580 | I12: 660 | J12: 660 | K12: 660 | M12: Overlapping branch and distribution-centre roles at Meridian in markets where the two networks overlap.
C13: Acquirer - SG&A Cost per Employee | D13: $ | G13: =Acquirer!G46 -> 78521.453 | H13: =Acquirer!H46 -> 80877.096 | I13: =Acquirer!I46 -> 83141.655 | J13: =Acquirer!J46 -> 85469.621 | K13: =Acquirer!K46 -> 87606.362
C14: Acquirer - Cost Savings | D14: $M | G14: =G12*G13/1000000 -> 31.408581 | H14: =H12*H13/1000000 -> 46.908716 | I14: =I12*I13/1000000 -> 54.873492 | J14: =J12*J13/1000000 -> 56.40995 | K14: =K12*K13/1000000 -> 57.820199
C16: Gross Run-Rate Expense Synergies | D16: $M | G16: =G10+G14 -> 57.45949 | H16: =H10+H14 -> 81.633045 | I16: =I10+I14 -> 95.437822 | J16: =J10+J14 -> 98.110081 | K16: =K10+K14 -> 100.56283
C17: (x) Realisation Factor | D17: % | G17: =Merger_Model!$E$12 -> 1 | H17: =Merger_Model!$E$12 -> 1 | I17: =Merger_Model!$E$12 -> 1 | J17: =Merger_Model!$E$12 -> 1 | K17: =Merger_Model!$E$12 -> 1 | M17: Master haircut on cost synergies, set on Merger_Model. 100% = management's plan delivered in full; this is the key variable in the EPS and IRR sensitivities.
C18: Realised Expense Synergies | D18: $M | G18: =G16*G17*Merger_Model!$E$11 -> 57.45949 | H18: =H16*H17*Merger_Model!$E$11 -> 81.633045 | I18: =I16*I17*Merger_Model!$E$11 -> 95.437822 | J18: =J16*J17*Merger_Model!$E$11 -> 98.110081 | K18: =K16*K17*Merger_Model!$E$11 -> 100.56283 | M18: Multiplied by the Include Expense Synergies switch (1/0) on Merger_Model.
B20: 2. REVENUE SYNERGIES — CROSS-SELL INTO THE ACQUIRER'S NETWORK | M20: Deliberately modest versus the sell-side case: only two of Calder's five segments are assumed to benefit, and only through Meridian's existing branches.
D21: ($ in millions) | G21: =Merger_Model!$G$89 -> 46387 | H21: =Merger_Model!$H$89 -> 46752 | I21: =Merger_Model!$I$89 -> 47118 | J21: =Merger_Model!$J$89 -> 47483 | K21: =Merger_Model!$K$89 -> 47848
C22: Uplift to Target Segment Revenue:
C23: Valves & Actuation | D23: % | G23: 0.04 | H23: 0.08 | I23: 0.12 | J23: 0.14 | K23: 0.14 | M23: Valves and pumps are the two lines Meridian's 230 branches can carry immediately; engineered assemblies and instrumentation need specification selling and are excluded.
C24: Pumps & Fluid Handling | D24: % | G24: 0.05 | H24: 0.1 | I24: 0.15 | J24: 0.18 | K24: 0.18
C26: (+) Incremental Revenue | D26: $M | G26: =G23*Target!G85*Merger_Model!$E$10+Synergies!G24*Target!G86*Merger_Model!$E$10 -> 76.412175 | H26: =H23*Target!H85*Merger_Model!$E$10+Synergies!H24*Target!H86*Merger_Model!$E$10 -> 160.47452 | I26: =I23*Target!I85*Merger_Model!$E$10+Synergies!I24*Target!I86*Merger_Model!$E$10 -> 251.91614 | J26: =J23*Target!J85*Merger_Model!$E$10+Synergies!J24*Target!J86*Merger_Model!$E$10 -> 310.94766 | K26: =K23*Target!K85*Merger_Model!$E$10+Synergies!K24*Target!K86*Merger_Model!$E$10 -> 322.64635
C27: (-) Incremental Cost of Sales | D27: $M | G27: =-G26*Target!G42 -> -53.870583 | H27: =-H26*Target!H42 -> -112.81359 | I27: =-I26*Target!I42 -> -176.59321 | J27: =-J26*Target!J42 -> -217.66336 | K27: =-K26*Target!K42 -> -225.85244 | M27: Costed at Calder's existing gross margin — no assumption that incremental volume is more profitable than the base business.
C28: (-) Incremental Operating Expenses | D28: $M | G28: =G26*Target!G95/Target!G90 -> -13.169942 | H28: =H26*Target!H95/Target!H90 -> -27.607945 | I28: =I26*Target!I95/Target!I90 -> -43.237515 | J28: =J26*Target!J95/Target!J90 -> -53.276199 | K28: =K26*Target!K95/Target!K90 -> -55.189099 | M28: Charged at Calder's existing SG&A margin, so the revenue synergy carries a full cost load rather than dropping straight to EBIT.
C29: Incremental Operating Income | D29: $M | G29: =SUM(G26:G28) -> 9.3716499 | H29: =SUM(H26:H28) -> 20.052987 | I29: =SUM(I26:I28) -> 32.085411 | J29: =SUM(J26:J28) -> 40.008098 | K29: =SUM(K26:K28) -> 41.604805
B31: 3. MERGER & INTEGRATION COSTS TO ACHIEVE | M31: Synergies are never free. Following the case convention, total costs to achieve equal 100% of the Year 3 run-rate cost synergy.
D32: ($ in millions) | G32: =Merger_Model!$G$89 -> 46387 | H32: =Merger_Model!$H$89 -> 46752 | I32: =Merger_Model!$I$89 -> 47118 | J32: =Merger_Model!$J$89 -> 47483 | K32: =Merger_Model!$K$89 -> 47848
C33: Integration Costs % of Year 3 Expense Synergies | D33: % | E33: 1
C34: Total Merger & Integration Costs | D34: $M | E34: =$E$33*I16*Merger_Model!$E$12 -> 95.437822 | M34: Sized off the GROSS Year 3 (FY28E) run-rate saving and scaled by the realisation factor — if you only capture half the savings you only spend half the cost to get them.
C35: Annual Recognition | D35: % | G35: 0.66666667 | H35: 0.33333333 | I35: 0 | J35: 0 | K35: 0 | M35: Severance, branch closure and systems-migration spend is front-loaded: two-thirds in Year 1, one-third in Year 2.
C36: Merger & Integration Costs | D36: $M | G36: =$E$34*G35 -> 63.625215 | H36: =$E$34*H35 -> 31.812607 | I36: =$E$34*I35 -> 0 | J36: =$E$34*J35 -> 0 | K36: =$E$34*K35 -> 0
B38: 4. NET PRE-TAX SYNERGY EFFECT
C40: Total Pre-Tax Synergies, Net of Costs to Achieve | D40: $M | G40: =G18+G29-G36 -> 3.2059251 | H40: =H18+H29-H36 -> 69.873424 | I40: =I18+I29-I36 -> 127.52323 | J40: =J18+J29-J36 -> 138.11818 | K40: =K18+K29-K36 -> 142.16764
C41: (-) Tax Effect | D41: $M | G41: =-G40*Acquirer!$E$10 -> -0.76942201 | H41: =-H40*Acquirer!$E$10 -> -16.769622 | I41: =-I40*Acquirer!$E$10 -> -30.605576 | J41: =-J40*Acquirer!$E$10 -> -33.148363 | K41: =-K40*Acquirer!$E$10 -> -34.120233
C42: After-Tax Synergies, Net of Costs to Achieve | D42: $M | G42: =G40+G41 -> 2.436503 | H42: =H40+H41 -> 53.103803 | I42: =I40+I41 -> 96.917657 | J42: =J40+J41 -> 104.96982 | K42: =K40+K41 -> 108.0474
B44: 5. VALUE OF SYNERGIES TO THE ACQUIRER vs. PREMIUM PAID | M44: The acid test: is the acquirer handing more value to the target's shareholders than the synergies are worth?
C46: Discount Rate (Acquirer's WACC) | D46: % | E46: =WACC!$F$44 -> 0.10390378
C47: Long-Term Growth Rate of Synergies | E47: 0.015 | G47: =Merger_Model!$G$89 -> 46387 | H47: =Merger_Model!$H$89 -> 46752 | I47: =Merger_Model!$I$89 -> 47118 | J47: =Merger_Model!$J$89 -> 47483 | K47: =Merger_Model!$K$89 -> 47848 | M47: Below long-run inflation — cost savings erode as wages reset and competitors respond.
C48: After-Tax Synergy Cash Flow | D48: $M | G48: =G42 -> 2.436503 | H48: =H42 -> 53.103803 | I48: =I42 -> 96.917657 | J48: =J42 -> 104.96982 | K48: =K42 -> 108.0474
C49: (+) Terminal Value of Synergies | D49: $M | K49: =K48*(1+$E$47)/($E$46-$E$47) -> 1233.5597 | M49: Perpetuity growth on the Year 5 after-tax run-rate. By then the costs to achieve are behind us, so this capitalises a clean recurring saving.
C50: Discount Period | D50: # yrs | G50: 1 | H50: 2 | I50: 3 | J50: 4 | K50: 5
C51: Present Value | D51: $M | G51: =(G48+G49)/(1+$E$46)^G50 -> 2.2071698 | H51: =(H48+H49)/(1+$E$46)^H50 -> 43.577587 | I51: =(I48+I49)/(1+$E$46)^I50 -> 72.045896 | J51: =(J48+J49)/(1+$E$46)^J50 -> 70.687001 | K51: =(K48+K49)/(1+$E$46)^K50 -> 818.40684
...

Sheet Combined_BS
B2: Balance Sheet Combination at Close — MIDS / CFFS
B3: ($ in millions, except per-share and per-unit data)
B4: Opening pro-forma balance sheet as at the 12/31/2025 close date. This is a point-in-time purchase-accounting exercise; the combined balance sheet is not projected forward.
B5: PRO-FORMA BALANCE SHEET AT CLOSE (FY25E) | M5: Column H isolates every acquisition adjustment so a reviewer can trace each one back to the Sources & Uses and the PPA.
D6: ($ in millions) | E6: Acquirer FY25E | F6: Target FY25E | G6: Combined | H6: Adjustments | I6: Pro-Forma
C7: ASSETS
C8: Cash & Cash Equivalents | D8: $M | E8: =Acquirer!F116 -> 362.16442 | F8: =Target!F116 -> 220.26067 | G8: =E8+F8 -> 582.42509 | H8: =-Merger_Model!E49-Merger_Model!E46-Merger_Model!E44*Merger_Model!E20-Merger_Model!E45*(Merger_Model!E50+Merger_Model!E21) -> -49.1124 | I8: =G8+H8 -> 533.31269 | M8: Cash consideration plus advisory, legal and debt financing fees all settle out of the combined cash balance at close.
C9: Accounts Receivable | D9: $M | E9: =Acquirer!F117 -> 825.0336 | F9: =Target!F117 -> 411.692 | G9: =E9+F9 -> 1236.7256 | H9: 0 | I9: =G9+H9 -> 1236.7256
C10: Inventory & Other Current Assets | D10: $M | E10: =Acquirer!F118 -> 969.86567 | F10: =Target!F118 -> 460.22832 | G10: =E10+F10 -> 1430.094 | H10: 0 | I10: =G10+H10 -> 1430.094
C11: Total Current Assets | D11: $M | E11: =SUM(E8:E10) -> 2157.0637 | F11: =SUM(F8:F10) -> 1092.181 | G11: =SUM(G8:G10) -> 3249.2447 | H11: =SUM(H8:H10) -> -49.1124 | I11: =SUM(I8:I10) -> 3200.1323
C13: Net Property, Plant & Equipment | D13: $M | E13: =Acquirer!F121 -> 590.02381 | F13: =Target!F121 -> 280.6259 | G13: =E13+F13 -> 870.64971 | H13: =Merger_Model!K75 -> 42.093885 | I13: =G13+H13 -> 912.74359 | M13: Written up to fair value per the PPA.
C14: Operating Lease Right-of-Use Assets | D14: $M | E14: =Acquirer!F122 -> 251.44894 | F14: =Target!F122 -> 84.088941 | G14: =E14+F14 -> 335.53788 | H14: 0 | I14: =G14+H14 -> 335.53788
C15: Goodwill | D15: $M | E15: =Acquirer!F123 -> 1120 | F15: =Target!F123 -> 470 | G15: =E15+F15 -> 1590 | H15: =-Target!F123+Merger_Model!E83 -> 1233.7025 | I15: =G15+H15 -> 2823.7025 | M15: Target's historical goodwill is written off in full and replaced with the goodwill created in this transaction.
C16: Other Intangible Assets | D16: $M | E16: =Acquirer!F124 -> 237.92858 | F16: =Target!F124 -> 188.47815 | G16: =E16+F16 -> 426.40674 | H16: =Merger_Model!K84 -> 377.6976 | I16: =G16+H16 -> 804.10433 | M16: Trade names and customer relationships recognised for the first time on acquisition.
C17: Other Long-Term Assets | D17: $M | E17: =Acquirer!F125 -> 48 | F17: =Target!F125 -> 26 | G17: =E17+F17 -> 74 | H17: 0 | I17: =G17+H17 -> 74
C18: Total Long-Term Assets | D18: $M | E18: =SUM(E13:E17) -> 2247.4013 | F18: =SUM(F13:F17) -> 1049.193 | G18: =SUM(G13:G17) -> 3296.5943 | H18: =SUM(H13:H17) -> 1653.494 | I18: =SUM(I13:I17) -> 4950.0883
C20: TOTAL ASSETS | D20: $M | E20: =E11+E18 -> 4404.465 | F20: =F11+F18 -> 2141.374 | G20: =G11+G18 -> 6545.839 | H20: =H11+H18 -> 1604.3816 | I20: =I11+I18 -> 8150.2206
C22: LIABILITIES & SHAREHOLDERS' EQUITY
C23: Accounts Payable | D23: $M | E23: =Acquirer!F131 -> 643.42308 | F23: =Target!F131 -> 239.70225 | G23: =E23+F23 -> 883.12533 | H23: 0 | I23: =G23+H23 -> 883.12533
C24: Accrued Liabilities | D24: $M | E24: =Acquirer!F132 -> 291.2536 | F24: =Target!F132 -> 123.79761 | G24: =E24+F24 -> 415.05121 | H24: 0 | I24: =G24+H24 -> 415.05121
C25: Total Current Liabilities | D25: $M | E25: =SUM(E23:E24) -> 934.67668 | F25: =SUM(F23:F24) -> 363.49986 | G25: =SUM(G23:G24) -> 1298.1765 | H25: =SUM(H23:H24) -> 0 | I25: =SUM(I23:I24) -> 1298.1765
C27: Existing Debt | D27: $M | E27: =Acquirer!F135 -> 1534.2 | F27: =Target!F135 -> 506.7 | G27: =E27+F27 -> 2040.9 | H27: =-Merger_Model!E21*Merger_Model!E45 -> -10.134 | I27: =G27+H27 -> 2030.766 | M27: Calder's debt is refinanced on identical terms so the principal is unchanged; only the capitalised financing fee moves the carrying value.
C28: New Transaction Debt | D28: $M | E28: 0 | F28: 0 | G28: =E28+F28 -> 0 | H28: =Merger_Model!$E$50-Merger_Model!E50*Merger_Model!$E$45 -> 0 | I28: =G28+H28 -> 0 | M28: Recognised net of capitalised issuance fees, which are then amortised to interest expense over the five-year term.
C29: Operating Lease Liabilities | D29: $M | E29: =Acquirer!F136 -> 251.44894 | F29: =Target!F136 -> 84.088941 | G29: =E29+F29 -> 335.53788 | H29: 0 | I29: =G29+H29 -> 335.53788
C30: Net Deferred Tax Liability | D30: $M | E30: =Acquirer!F137 -> 74.832461 | F30: =Target!F137 -> 12.537624 | G30: =E30+F30 -> 87.370085 | H30: =-Target!F137+Merger_Model!K86 -> 88.212333 | I30: =G30+H30 -> 175.58242 | M30: Historical DTL is eliminated and a new one booked on the non-deductible asset write-ups.
C31: Other Long-Term Liabilities | D31: $M | E31: =Acquirer!F138 -> 88.024945 | F31: =Target!F138 -> 41.98924 | G31: =E31+F31 -> 130.01418 | H31: 0 | I31: =G31+H31 -> 130.01418
C32: Total Long-Term Liabilities | D32: $M | E32: =SUM(E27:E31) -> 1948.5063 | F32: =SUM(F27:F31) -> 645.3158 | G32: =SUM(G27:G31) -> 2593.8222 | H32: =SUM(H27:H31) -> 78.078333 | I32: =SUM(I27:I31) -> 2671.9005
C34: Total Liabilities | D34: $M | E34: =E25+E32 -> 2883.183 | F34: =F25+F32 -> 1008.8157 | G34: =G25+G32 -> 3891.9987 | H34: =H25+H32 -> 78.078333 | I34: =I25+I32 -> 3970.077
C36: Common Shareholders' Equity | D36: $M | E36: =Acquirer!F143 -> 1521.282 | F36: =Target!F143 -> 1132.5583 | G36: =E36+F36 -> 2653.8403 | H36: =-Target!F143+Merger_Model!E51-Merger_Model!E46-Merger_Model!E44*Merger_Model!E20 -> 1526.3033 | I36: =G36+H36 -> 4180.1436 | M36: Target's book equity is eliminated, the stock consideration is added to the acquirer's equity, and advisory and legal fees are expensed straight against equity.
C38: TOTAL LIABILITIES & EQUITY | D38: $M | E38: =E34+E36 -> 4404.465 | F38: =F34+F36 -> 2141.374 | G38: =G34+G36 -> 6545.839 | H38: =H34+H36 -> 1604.3816 | I38: =I34+I36 -> 8150.2206
C40: Balance Sheet Check (must equal zero) | D40: $M | E40: =ROUND(E20-E38,6) -> 0 | F40: =ROUND(F20-F38,6) -> 0 | G40: =ROUND(G20-G38,6) -> 0 | H40: =ROUND(H20-H38,6) -> 0 | I40: =ROUND(I20-I38,6) -> 0

Sheet DCF_IRR
B2: Calder Fluid & Flow Systems, Inc. - Discounted Cash Flow Valuation & Acquisition IRR
B3: ($ in millions, except per-share and per-unit data)
B4: Ten-year unlevered DCF on Calder standalone, plus the IRR the acquirer earns on the purchase price once synergies are included. Notes are in column R.
B5: 1. DCF ASSUMPTIONS & OUTPUT
C7: Discount Rate (Target WACC) | E7: =WACC!E44 -> 0.10573578 | R7: Pulled from the WACC tab — Calder's own capital structure, not the acquirer's.
C8: Mid-Year Convention (1 = Yes, 0 = No) | E8: 1 | R8: Cash flows are assumed to arrive evenly through the year rather than all on 31 December.
C9: Terminal FCF Growth Rate | E9: 0.0225 | R9: Below long-run nominal GDP. Higher than it would have been a decade ago because the whole rate and inflation structure is higher — the discount rate reflects the same shift.
C10: Terminal EBITDA Multiple | E10: 8.5 | R10: Cross-check on the growth method; set slightly below today's trading comps to reflect a more mature business by FY34.
C11: Terminal Discount Period | E11: 9 | R11: The terminal value is struck at the end of FY34 and discounted a full nine years, even under the mid-year convention.
E14: Perpetuity Growth | G14: Terminal Multiple
C15: Sum of PV of Unlevered Free Cash Flow | E15: =SUM(G54:P54) -> 1479.3361 | G15: =E15 -> 1479.3361
C16: Terminal Value | E16: =P49*(1+$E$9)/($E$7-$E$9) -> 3598.8465 | G16: =$E$10*P56 -> 4147.3936 | R16: Two independent routes to the same question: capitalise the final cash flow, or apply an exit multiple to final-year EBITDA.
C17: PV of Terminal Value | E17: =E16/(1+$E$7)^$E$11 -> 1456.4684 | G17: =G16/(1+$E$7)^$E$11 -> 1678.4678
C18: Implied Enterprise Value | E18: =E15+E17 -> 2935.8045 | G18: =G15+G17 -> 3157.8039
C19: % of Implied TEV from Terminal Value | E19: =E17/E18 -> 0.49610538 | G19: =G17/G18 -> 0.53153008 | R19: Above roughly 75% the valuation is really a bet on the terminal assumption rather than on the forecast.
C20: (+) Cash & Cash Equivalents | E20: =Target!$F$116 -> 220.26067 | G20: =E20 -> 220.26067
C21: (-) Total Debt | E21: =-Target!F135 -> -506.7 | G21: =E21 -> -506.7
C22: Net Cash / (Debt) Bridge | E22: =E20+E21 -> -286.43933 | G22: =E22 -> -286.43933
C23: Implied Equity Value | E23: =E18+E22 -> 2649.3652 | G23: =G18+G22 -> 2871.3645
C24: Diluted Shares Outstanding | E24: =Target!$E$15 -> 55.593651 | G24: =E24 -> 55.593651
C25: Implied Share Price | E25: =E23/E24 -> 47.655895 | G25: =G23/G24 -> 51.649145
C26: Premium / (Discount) to Current Price | E26: =E25/Target!E11-1 -> 0.26073797 | G26: =G25/Target!E11-1 -> 0.3663795 | R26: Compare against the 14% offer premium — this is the core evidence for case question 2.
C28: Implied Terminal FCF Growth (from the multiple method) | E28: =($E$7*G16-P49)/(G16+P49) -> 0.032782679
C29: Implied Terminal EBITDA Multiple (from the growth method) | E29: =E16/P56 -> 7.3757637 | R29: Sanity check: each method should imply a sensible value for the other's key input. Large divergence means one of the two is wrong.
B31: 2. UNLEVERED FREE CASH FLOW PROJECTIONS | L31: extended | M31: FY25E-FY30E link directly to the Target operating model; FY31E-FY34E are extended here with fading growth and stable margins. | N31: extended | O31: extended | P31: extended
D32: ($ in millions) | F32: =Merger_Model!$F$89 -> 46022 | G32: =Merger_Model!$G$89 -> 46387 | H32: =Merger_Model!$H$89 -> 46752 | I32: =Merger_Model!$I$89 -> 47118 | J32: =Merger_Model!$J$89 -> 47483 | K32: =Merger_Model!$K$89 -> 47848 | L32: =EOMONTH(K32,12) -> 48213 | N32: =EOMONTH(L32,12) -> 48579 | O32: =EOMONTH(N32,12) -> 48944 | P32: =EOMONTH(O32,12) -> 49309
C33: Total Revenue | D33: $M | F33: =Target!F90 -> 2708.5 | G33: =Target!G90 -> 2854.0245 | H33: =Target!H90 -> 3000.0668 | I33: =Target!I90 -> 3143.3389 | J33: =Target!J90 -> 3280.8122 | K33: =Target!K90 -> 3408.3886 | L33: =K33*(1+L34) -> 3510.6402 | N33: =L33*(1+N34) -> 3608.9381 | O33: =N33*(1+O34) -> 3699.1616 | P33: =O33*(1+P34) -> 3782.3927
C34: Growth Rate | D34: % | F34: =Target!F194 -> 0.047775629 | G34: =Target!G194 -> 0.053728817 | H34: =Target!H194 -> 0.051170669 | I34: =Target!I194 -> 0.047756296 | J34: =Target!J194 -> 0.043734786 | K34: =Target!K194 -> 0.038885611 | L34: 0.03 | N34: 0.028 | O34: 0.025 | P34: 0.0225 | R34: Growth fades from 3.0% to 2.25% by FY34 so that the terminal year is a genuine steady state consistent with the terminal growth rate above.
C36: Earnings Before Interest & Taxes (EBIT) | D36: $M | F36: =Target!F102 -> 258.94677 | G36: =Target!G102 -> 285.38785 | H36: =Target!H102 -> 310.68862 | I36: =Target!I102 -> 334.0283 | J36: =Target!J102 -> 353.885 | K36: =Target!K102 -> 369.29423 | L36: =L33*L37 -> 384.4151 | N36: =N33*N37 -> 395.17873 | O36: =O33*O37 -> 403.20861 | P36: =P33*P37 -> 412.28081
C37: EBIT Margin | D37: % | F37: =F36/F33 -> 0.09560523 | G37: =G36/G33 -> 0.099994883 | H37: =H36/H33 -> 0.10356057 | I37: =I36/I33 -> 0.10626544 | J37: =J36/J33 -> 0.10786506 | K37: =K36/K33 -> 0.10834863 | L37: 0.1095 | N37: 0.1095 | O37: 0.109 | P37: 0.109 | R37: Held flat at roughly the FY30E level — margin expansion is assumed to stop once the business is mature.
C38: (-) Taxes on EBIT | D38: $M | F38: =-F36*Target!$E$10 -> -63.441957 | G38: =-G36*Target!$E$10 -> -69.920022 | H38: =-H36*Target!$E$10 -> -76.118713 | I38: =-I36*Target!$E$10 -> -81.836934 | J38: =-J36*Target!$E$10 -> -86.701824 | K38: =-K36*Target!$E$10 -> -90.477087 | L38: =-L36*Target!$E$10 -> -94.181701 | N38: =-N36*Target!$E$10 -> -96.818788 | O38: =-O36*Target!$E$10 -> -98.786111 | P38: =-P36*Target!$E$10 -> -101.0088 | R38: Taxed at the full unlevered rate — the interest tax shield belongs in the WACC, not the cash flow.
C39: Net Operating Profit After Tax (NOPAT) | D39: $M | F39: =F36+F38 -> 195.50481 | G39: =G36+G38 -> 215.46782 | H39: =H36+H38 -> 234.56991 | I39: =I36+I38 -> 252.19137 | J39: =J36+J38 -> 267.18317 | K39: =K36+K38 -> 278.81715 | L39: =L36+L38 -> 290.2334 | N39: =N36+N38 -> 298.35994 | O39: =O36+O38 -> 304.4225 | P39: =P36+P38 -> 311.27201
C41: (+) Depreciation & Amortisation | D41: $M | F41: =Target!F152+Target!F153 -> 58.77445 | G41: =Target!G152+Target!G153 -> 61.646929 | H41: =Target!H152+Target!H153 -> 64.20143 | I41: =Target!I152+Target!I153 -> 66.324451 | J41: =Target!J152+Target!J153 -> 68.240893 | K41: =Target!K152+Target!K153 -> 70.212804 | L41: =L33*L42 -> 70.212804 | N41: =N33*N42 -> 72.178763 | O41: =O33*O42 -> 73.983232 | P41: =P33*P42 -> 75.647855
C42: % of Revenue | D42: % | F42: =F41/F33 -> 0.0217 | G42: =G41/G33 -> 0.0216 | H42: =H41/H33 -> 0.0214 | I42: =I41/I33 -> 0.0211 | J42: =J41/J33 -> 0.0208 | K42: =K41/K33 -> 0.0206 | L42: 0.02 | N42: 0.02 | O42: 0.02 | P42: 0.02
C43: (+/-) Deferred Income Taxes | D43: $M | F43: =Target!F157 -> 4.5376238 | G43: =Target!G157 -> 3.8835117 | H43: =Target!H157 -> 3.6331117 | I43: =Target!I157 -> 3.2135433 | J43: =Target!J157 -> 3.4944168 | K43: =Target!K157 -> 3.7400256 | L43: =0 -> 0 | N43: =0 -> 0 | O43: =0 -> 0 | P43: =0 -> 0
C44: (+/-) Change in Working Capital | D44: $M | F44: =Target!F166 -> -21.339141 | G44: =Target!G166 -> -22.402974 | H44: =Target!H166 -> -22.516544 | I44: =Target!I166 -> -23.861421 | J44: =Target!J166 -> -22.846812 | K44: =Target!K166 -> -23.589371 | L44: =-(L33-K33)*L45 -> -22.495365 | N44: =-(N33-L33)*N45 -> -21.625544 | O44: =-(O33-N33)*O45 -> -19.84916 | P44: =-(P33-O33)*P45 -> -18.31085
C45: % of Change in Revenue | D45: % | F45: =IFERROR(-F44/(F33-E33),0) -> 0.0078785826 | G45: =IFERROR(-G44/(G33-F33),0) -> 0.15394641 | H45: =IFERROR(-H44/(H33-G33),0) -> 0.15417819 | I45: =IFERROR(-I44/(I33-H33),0) -> 0.1665462 | J45: =IFERROR(-J44/(J33-I33),0) -> 0.16619096 | K45: =IFERROR(-K44/(K33-J33),0) -> 0.1849039 | L45: 0.22 | N45: 0.22 | O45: 0.22 | P45: 0.22 | R45: Growth consumes working capital: roughly 22 cents of receivables and inventory for every extra dollar of revenue.
C46: (-) Capital Expenditures, Net of Disposals | D46: $M | F46: =Target!F169+Target!F170 -> -54.8785 | G46: =Target!G169+Target!G170 -> -56.507502 | H46: =Target!H169+Target!H170 -> -58.001337 | I46: =Target!I169+Target!I170 -> -59.295109 | J46: =Target!J169+Target!J170 -> -60.335431 | K46: =Target!K169+Target!K170 -> -62.759383 | L46: =-L33*L47 -> -66.702164 | N46: =-N33*N47 -> -68.569825 | O46: =-O33*O47 -> -72.133651 | P46: =-P33*P47 -> -75.647855
C47: % of Revenue | D47: % | F47: =-F46/F33 -> 0.020261584 | G47: =-G46/G33 -> 0.019799235 | H47: =-H46/H33 -> 0.019333348 | I47: =-I46/I33 -> 0.018863734 | J47: =-J46/J33 -> 0.018390395 | K47: =-K46/K33 -> 0.018413212 | L47: 0.019 | N47: 0.019 | O47: 0.0195 | P47: 0.02 | R47: Net capex converges toward D&A by FY34, consistent with a business no longer adding capacity.
C49: Unlevered Free Cash Flow | D49: $M | F49: =F39+F41+F43+F44+F46 -> 182.59924 | G49: =G39+G41+G43+G44+G46 -> 202.08779 | H49: =H39+H41+H43+H44+H46 -> 221.88657 | I49: =I39+I41+I43+I44+I46 -> 238.57283 | J49: =J39+J41+J43+J44+J46 -> 255.73624 | K49: =K39+K41+K43+K44+K46 -> 266.42122 | L49: =L39+L41+L43+L44+L46 -> 271.24868 | N49: =N39+N41+N43+N44+N46 -> 280.34333 | O49: =O39+O41+O43+O44+O46 -> 286.42292 | P49: =P39+P41+P43+P44+P46 -> 292.96116
...

Sheet WACC
B2: Weighted Average Cost of Capital — Discount Rate Derivation
B3: ($ in millions, except per-share and per-unit data)
B4: One unlevered beta is drawn from the peer group and re-levered to each company's own capital structure, giving a target WACC for the DCF and an acquirer WACC for valuing synergies and the deal IRR.
B5: 1. MARKET ASSUMPTIONS
B7: Risk-Free Rate | F7: 0.0425 | M7: 10-year government bond yield at the analysis date.
B8: Equity Risk Premium | F8: 0.055 | M8: Long-run supply-side premium for a developed market.
B9: Marginal Tax Rate (used to unlever peer betas) | F9: 0.24
B11: 2. PEER GROUP — UNLEVERING OBSERVED BETAS | M11: Hamada: Unlevered Beta = Levered Beta / (1 + (1 - t) x Debt / Equity). Strips out each peer's financing decision.
B12: Company | C12: Ticker | D12: Levered Beta | E12: Total Debt | F12: Equity Value | G12: Debt / Equity | H12: Unlevered Beta
B13: Anchorpoint Industrial Group | C13: APIG | D13: 1.42 | E13: =Pub_Comps!H9 -> 1180 | F13: =Pub_Comps!F9 -> 4453.68 | G13: =E13/F13 -> 0.26494944 | H13: =D13/(1+(1-$F$9)*G13) -> 1.1819922
B14: Ardent Flow Technologies | C14: ARFT | D14: 1.31 | E14: =Pub_Comps!H10 -> 690 | F14: =Pub_Comps!F10 -> 2951.65 | G14: =E14/F14 -> 0.23376755 | H14: =D14/(1+(1-$F$9)*G14) -> 1.1123722
B15: Castellan Supply Holdings | C15: CSLH | D15: 1.88 | E15: =Pub_Comps!H11 -> 2240 | F15: =Pub_Comps!F11 -> 3104.64 | G15: =E15/F15 -> 0.72150072 | H15: =D15/(1+(1-$F$9)*G15) -> 1.2142032
B16: Delaney Process Solutions | C16: DLPS | D16: 1.24 | E16: =Pub_Comps!H12 -> 415 | F16: =Pub_Comps!F12 -> 2482.35 | G16: =E16/F16 -> 0.16718029 | H16: =D16/(1+(1-$F$9)*G16) -> 1.1002105
B17: Ellsworth Bearing & Drive | C17: EBDC | D17: 1.61 | E17: =Pub_Comps!H13 -> 985 | F17: =Pub_Comps!F13 -> 2837.32 | G17: =E17/F17 -> 0.34715859 | H17: =D17/(1+(1-$F$9)*G17) -> 1.2738949
B18: Harlow Valve & Controls | C18: HVCX | D18: 1.36 | E18: =Pub_Comps!H14 -> 560 | F18: =Pub_Comps!F14 -> 2317.07 | G18: =E18/F18 -> 0.24168454 | H18: =D18/(1+(1-$F$9)*G18) -> 1.1489589
B19: Kestrel MRO Distribution | C19: KMRO | D19: 2.05 | E19: =Pub_Comps!H15 -> 3120 | F19: =Pub_Comps!F15 -> 3890.435 | G19: =E19/F19 -> 0.80196688 | H19: =D19/(1+(1-$F$9)*G19) -> 1.2736916
B20: Northvale Fasteners | C20: NVFS | D20: 1.18 | E20: =Pub_Comps!H16 -> 340 | F20: =Pub_Comps!F16 -> 2360.28 | G20: =E20/F20 -> 0.14405071 | H20: =D20/(1+(1-$F$9)*G20) -> 1.0635627
B21: Sable Point Industrial | C21: SPIN | D21: 1.72 | E21: =Pub_Comps!H17 -> 1675 | F21: =Pub_Comps!F17 -> 3757.24 | G21: =E21/F21 -> 0.44580596 | H21: =D21/(1+(1-$F$9)*G21) -> 1.2847206
B22: Trellis Flow Group | C22: TRFG | D22: 1.49 | E22: =Pub_Comps!H18 -> 820 | F22: =Pub_Comps!F18 -> 2608.925 | G22: =E22/F22 -> 0.3143057 | H22: =D22/(1+(1-$F$9)*G22) -> 1.2027067
B24: Median | D24: =MEDIAN(D13:D22) -> 1.455 | G24: =MEDIAN(G13:G22) -> 0.28962757 | H24: =MEDIAN(H13:H22) -> 1.1923494
B26: 3. RE-LEVERED BETA, COST OF EQUITY AND WACC
E27: Target (CFFS) | F27: Acquirer (MIDS)
B28: Median Unlevered Beta (peer group) | E28: =$H$24 -> 1.1923494 | F28: =$H$24 -> 1.1923494
B29: Total Debt | E29: =Target!$E$19 -> 545 | F29: =Acquirer!$E$19 -> 1650
B30: Equity Value | E30: =Target!E17 -> 2101.44 | F30: =Acquirer!$E$17 -> 4095.35
B31: Debt / Equity | E31: =E29/E30 -> 0.25934597 | F31: =F29/F30 -> 0.40289597
B32: Effective Tax Rate | E32: =Target!$E$10 -> 0.245 | F32: =Acquirer!$E$10 -> 0.24
B33: Re-Levered Beta | E33: =$H$24*(1+(1-E32)*E31) -> 1.4258188 | F33: =$H$24*(1+(1-F32)*F31) -> 1.5574479 | M33: Re-levered to each company's own capital structure — the acquirer carries more leverage, so it earns a higher beta.
B34: Cost of Equity (Rf + Beta x ERP) | E34: =$F$7+E33*$F$8 -> 0.12092004 | F34: =$F$7+F33*$F$8 -> 0.12815964
B36: Pre-Tax Cost of Debt | E36: =Target!$F$75 -> 0.0625 | F36: =Acquirer!F75 -> 0.0575 | M36: Each company's own blended borrowing rate, taken straight from its operating model.
B37: After-Tax Cost of Debt | E37: =E36*(1-E32) -> 0.0471875 | F37: =F36*(1-F32) -> 0.0437
B39: % Equity | E39: =E30/(E29+E30) -> 0.79406297 | F39: =F30/(F29+F30) -> 0.71281123
B40: % Debt | E40: =E29/(E29+E30) -> 0.20593703 | F40: =F29/(F29+F30) -> 0.28718877
B42: WACC = Cost of Equity x % Equity + After-Tax Cost of Debt x % Debt
B44: WACC — Current Capital Structure | E44: =E34*E39+E37*E40 -> 0.10573578 | F44: =F34*F39+F37*F40 -> 0.10390378 | M44: E44 discounts Calder's cash flows in the DCF. F44 discounts the synergies and is the hurdle rate for the deal IRR.

Sheet Pub_Comps
B2: Comparable Public Companies - North American Industrial Distributors & Flow-Control Suppliers
B3: ($ in millions, except per-share and per-unit data)
B4: Screened for revenue of $1bn-$8bn and a comparable end-market mix. Meridian and Calder are shown inside the set, with their statistics linked live from their own tabs.
B5: OPERATING & VALUATION STATISTICS | M5: TEV excludes operating lease liabilities on the same basis as the company tabs, so the multiples are directly comparable.
B8: Company | C8: Ticker | D8: Share Price | E8: Diluted Shares | F8: Equity Value | G8: Cash | H8: Total Debt | I8: Enterprise Value | J8: FY25E Revenue | K8: FY26E Revenue | L8: FY25E EBITDA | M8: FY26E EBITDA | N8: FY25E EBITDA Margin | O8: TEV / FY25E Rev | P8: TEV / FY25E EBITDA | Q8: TEV / FY26E EBITDA
B9: Anchorpoint Industrial Group | C9: APIG | D9: 48.2 | E9: 92.4 | F9: =D9*E9 -> 4453.68 | G9: 240 | H9: 1180 | I9: =F9-G9+H9 -> 5393.68 | J9: 4180 | K9: 4420 | L9: 505 | M9: 555 | N9: =L9/J9 -> 0.1208134 | O9: =I9/J9 -> 1.2903541 | P9: =I9/L9 -> 10.680554 | Q9: =I9/M9 -> 9.7183423
B10: Ardent Flow Technologies | C10: ARFT | D10: 61.75 | E10: 47.8 | F10: =D10*E10 -> 2951.65 | G10: 165 | H10: 690 | I10: =F10-G10+H10 -> 3476.65 | J10: 1780 | K10: 1900 | L10: 278 | M10: 308 | N10: =L10/J10 -> 0.15617978 | O10: =I10/J10 -> 1.9531742 | P10: =I10/L10 -> 12.505935 | Q10: =I10/M10 -> 11.287825
B11: Castellan Supply Holdings | C11: CSLH | D11: 22.4 | E11: 138.6 | F11: =D11*E11 -> 3104.64 | G11: 118 | H11: 2240 | I11: =F11-G11+H11 -> 5226.64 | J11: 5640 | K11: 5880 | L11: 560 | M11: 615 | N11: =L11/J11 -> 0.09929078 | O11: =I11/J11 -> 0.92670922 | P11: =I11/L11 -> 9.3332857 | Q11: =I11/M11 -> 8.4986016
B12: Delaney Process Solutions | C12: DLPS | D12: 74.1 | E12: 33.5 | F12: =D12*E12 -> 2482.35 | G12: 205 | H12: 415 | I12: =F12-G12+H12 -> 2692.35 | J12: 1240 | K12: 1320 | L12: 205 | M12: 228 | N12: =L12/J12 -> 0.16532258 | O12: =I12/J12 -> 2.17125 | P12: =I12/L12 -> 13.133415 | Q12: =I12/M12 -> 11.808553
B13: Ellsworth Bearing & Drive | C13: EBDC | D13: 39.85 | E13: 71.2 | F13: =D13*E13 -> 2837.32 | G13: 96 | H13: 985 | I13: =F13-G13+H13 -> 3726.32 | J13: 2860 | K13: 3010 | L13: 340 | M13: 374 | N13: =L13/J13 -> 0.11888112 | O13: =I13/J13 -> 1.3029091 | P13: =I13/L13 -> 10.959765 | Q13: =I13/M13 -> 9.9634225
B14: Harlow Valve & Controls | C14: HVCX | D14: 55.3 | E14: 41.9 | F14: =D14*E14 -> 2317.07 | G14: 142 | H14: 560 | I14: =F14-G14+H14 -> 2735.07 | J14: 1510 | K14: 1615 | L14: 228 | M14: 252 | N14: =L14/J14 -> 0.15099338 | O14: =I14/J14 -> 1.8113046 | P14: =I14/L14 -> 11.995921 | Q14: =I14/M14 -> 10.853452
B15: Kestrel MRO Distribution | C15: KMRO | D15: 18.95 | E15: 205.3 | F15: =D15*E15 -> 3890.435 | G15: 88 | H15: 3120 | I15: =F15-G15+H15 -> 6922.435 | J15: 7320 | K15: 7610 | L15: 730 | M15: 800 | N15: =L15/J15 -> 0.099726776 | O15: =I15/J15 -> 0.94568784 | P15: =I15/L15 -> 9.4827877 | Q15: =I15/M15 -> 8.6530438
B16: Northvale Fasteners | C16: NVFS | D16: 88.4 | E16: 26.7 | F16: =D16*E16 -> 2360.28 | G16: 310 | H16: 340 | I16: =F16-G16+H16 -> 2390.28 | J16: 985 | K16: 1045 | L16: 185 | M16: 202 | N16: =L16/J16 -> 0.18781726 | O16: =I16/J16 -> 2.4266802 | P16: =I16/L16 -> 12.920432 | Q16: =I16/M16 -> 11.833069
B17: Sable Point Industrial | C17: SPIN | D17: 31.6 | E17: 118.9 | F17: =D17*E17 -> 3757.24 | G17: 130 | H17: 1675 | I17: =F17-G17+H17 -> 5302.24 | J17: 3940 | K17: 4130 | L17: 490 | M17: 540 | N17: =L17/J17 -> 0.12436548 | O17: =I17/J17 -> 1.3457462 | P17: =I17/L17 -> 10.820898 | Q17: =I17/M17 -> 9.818963
B18: Trellis Flow Group | C18: TRFG | D18: 44.75 | E18: 58.3 | F18: =D18*E18 -> 2608.925 | G18: 178 | H18: 820 | I18: =F18-G18+H18 -> 3250.925 | J18: 2240 | K18: 2390 | L18: 285 | M18: 315 | N18: =L18/J18 -> 0.12723214 | O18: =I18/J18 -> 1.4513058 | P18: =I18/L18 -> 11.406754 | Q18: =I18/M18 -> 10.320397
B19: Meridian Industrial Supply, Inc. | C19: MIDS | D19: =Acquirer!E11 -> 34.5 | E19: =Acquirer!E15 -> 118.7058 | F19: =D19*E19 -> 4095.35 | G19: =Acquirer!F116 -> 362.16442 | H19: =Acquirer!F135 -> 1534.2 | I19: =F19-G19+H19 -> 5267.3856 | J19: =Acquirer!F90 -> 6445.575 | K19: =Acquirer!G90 -> 6756.087 | L19: =Acquirer!F192 -> 635.80591 | M19: =Acquirer!G192 -> 675.99633 | N19: =L19/J19 -> 0.098642232 | O19: =I19/J19 -> 0.81720957 | P19: =I19/L19 -> 8.2845811 | Q19: =I19/M19 -> 7.7920329 | R19: Linked live from the Acquirer tab - the comp set updates automatically if the operating model changes.
B20: Calder Fluid & Flow Systems, Inc. | C20: CFFS | D20: =Target!E11 -> 37.8 | E20: =Target!E15 -> 55.593651 | F20: =D20*E20 -> 2101.44 | G20: =Target!F116 -> 220.26067 | H20: =Target!F135 -> 506.7 | I20: =F20-G20+H20 -> 2387.8793 | J20: =Target!F90 -> 2708.5 | K20: =Target!G90 -> 2854.0245 | L20: =Target!F192 -> 317.72122 | M20: =Target!G192 -> 347.03477 | N20: =L20/J20 -> 0.11730523 | O20: =I20/J20 -> 0.88162427 | P20: =I20/L20 -> 7.5156433 | Q20: =I20/M20 -> 6.8808071
B22: Maximum | N22: =MAX(N9:N20) -> 0.18781726 | O22: =MAX(O9:O20) -> 2.4266802 | P22: =MAX(P9:P20) -> 13.133415 | Q22: =MAX(Q9:Q20) -> 11.833069
B23: 75th Percentile | N23: =QUARTILE(N9:N20,3) -> 0.15228998 | O23: =QUARTILE(O9:O20,3) -> 1.846772 | P23: =QUARTILE(P9:P20,3) -> 12.123425 | Q23: =QUARTILE(Q9:Q20,3) -> 10.962045
B24: Median | N24: =MEDIAN(N9:N20) -> 0.12258944 | O24: =MEDIAN(O9:O20) -> 1.3243276 | P24: =MEDIAN(P9:P20) -> 10.890331 | Q24: =MEDIAN(Q9:Q20) -> 9.8911927 | R24: The median is the reference point used on the Merger_Model and Value_Creation tabs. Note that Meridian trades below the peer median — the reason a 100% stock deal is expensive for its shareholders.
B25: 25th Percentile | N25: =QUARTILE(N9:N20,1) -> 0.11291062 | O25: =QUARTILE(O9:O20,1) -> 0.94094319 | P25: =QUARTILE(P9:P20,1) -> 9.4454122 | Q25: =QUARTILE(Q9:Q20,1) -> 8.6144332
B26: Minimum | N26: =MIN(N9:N20) -> 0.098642232 | O26: =MIN(O9:O20) -> 0.81720957 | P26: =MIN(P9:P20) -> 7.5156433 | Q26: =MIN(Q9:Q20) -> 6.8808071

Sheet MA_Comps
B2: Precedent Transactions -Industrial Distribution & Flow Control
B3: ($ in millions, except per-share and per-unit data)
B4: Control transactions announced 2020-2024 with enterprise values between $700m and $4bn in comparable end markets.
B5: SELECTED PRECEDENT TRANSACTIONS | M5: Precedents carry a control premium, so they typically print above the trading comps.
B8: Acquirer | C8: Target | D8: Announced | E8: Enterprise Value | F8: LTM Revenue | G8: LTM EBITDA | H8: TEV / Revenue | I8: TEV / EBITDA
B9: Anchorpoint Industrial Group | C9: Verity Bearing Corporation | D9: Nov-2024 | E9: 1285 | F9: 640 | G9: 118 | H9: =E9/F9 -> 2.0078125 | I9: =E9/G9 -> 10.889831
B10: Kestrel MRO Distribution | C10: Thorne Pipe & Supply Co. | D10: Jun-2024 | E10: 2340 | F10: 1480 | G10: 208 | H10: =E10/F10 -> 1.5810811 | I10: =E10/G10 -> 11.25
B11: Sable Point Industrial | C11: Redgate Fastener Group | D11: Feb-2024 | E11: 985 | F11: 520 | G11: 92 | H11: =E11/F11 -> 1.8942308 | I11: =E11/G11 -> 10.706522
B12: Hollis Capital Partners | C12: Marchand Flow Group | D12: Sep-2023 | E12: 1760 | F12: 1105 | G12: 172 | H12: =E12/F12 -> 1.5927602 | I12: =E12/G12 -> 10.232558
B13: Trellis Flow Group | C13: Ostrander Valve Company | D13: Apr-2023 | E13: 745 | F13: 385 | G13: 71 | H13: =E13/F13 -> 1.9350649 | I13: =E13/G13 -> 10.492958
B14: Castellan Supply Holdings | C14: Pinehurst Industrial Distribution | D14: Nov-2022 | E14: 3120 | F14: 2650 | G14: 312 | H14: =E14/F14 -> 1.1773585 | I14: =E14/G14 -> 10
B15: Ellsworth Bearing & Drive | C15: Caldicott Power Products | D15: May-2021 | E15: 1420 | F15: 890 | G15: 142 | H15: =E15/F15 -> 1.5955056 | I15: =E15/G15 -> 10
B16: Brightwater Partners LLC | C16: Halvorsen Process Equipment | D16: Aug-2020 | E16: 1095 | F16: 610 | G16: 96 | H16: =E16/F16 -> 1.795082 | I16: =E16/G16 -> 11.40625
C19: Maximum | H19: =MAX(H9:H16) -> 2.0078125 | I19: =MAX(I9:I16) -> 11.40625
C20: 75th Percentile | H20: =QUARTILE(H9:H16,3) -> 1.9044393 | I20: =QUARTILE(I9:I16,3) -> 10.979873
C21: Median | H21: =MEDIAN(H9:H16) -> 1.6952938 | I21: =MEDIAN(I9:I16) -> 10.59974
C22: 25th Percentile | H22: =QUARTILE(H9:H16,1) -> 1.5898404 | I22: =QUARTILE(I9:I16,1) -> 10.174419
C23: Minimum | H23: =MIN(H9:H16) -> 1.1773585 | I23: =MIN(I9:I16) -> 10
C25: This Transaction -Calder Fluid & Flow Systems | H25: =Merger_Model!$E$25 -> 1.1018199 | I25: =Merger_Model!$E$27 -> 9.3927607 | K25: The proposed price sits below the precedent median -the basis for arguing the offer is fair to Meridian, and that Calder's board may push for more.

Sheet Contrib
B2: Relative Contribution Analysis -MIDS / CFFS
B3: ($ in millions, except per-share and per-unit data)
B4: Asks a different question from a DCF: if each side contributes X% of the combined company's earnings, should it not own X% of it? Each metric implies its own 'fair' exchange ratio.
B5: 1. CONTRIBUTION BY METRIC | M5: Ownership under the proposed deal is shown at the bottom for comparison against each metric's implied split.
D7: Acquirer | E7: Target | F7: Combined | G7: Acquirer % | H7: Target % | I7: Implied Combined Equity Value | J7: Target Implied Equity Value | K7: Implied Exchange Ratio | L7: Implied Price / Share | M7: Implied Premium
C8: Equity Value (Undisturbed) | D8: =Acquirer!$E$17 -> 4095.35 | E8: =Target!$E$17 -> 2101.44 | F8: =D8+E8 -> 6196.79 | G8: =D8/F8 -> 0.66088249 | H8: =E8/F8 -> 0.33911751 | I8: =Acquirer!$E$17/G8 -> 6196.79 | J8: =I8*H8 -> 2101.44 | K8: =L8/Acquirer!$E$11 -> 1.0956522 | L8: =J8/Target!$E$15 -> 37.8 | M8: =L8/Target!$E$11-1 -> 0 | O8: Combined equity value is inferred as the acquirer's own market value divided by its contribution percentage -i.e. the market's view of Meridian is taken as given and Calder is valued off it.
C9: Revenue -FY26E | D9: =Acquirer!G90 -> 6756.087 | E9: =Target!G90 -> 2854.0245 | F9: =D9+E9 -> 9610.1115 | G9: =D9/F9 -> 0.70301859 | H9: =E9/F9 -> 0.29698141 | I9: =Acquirer!$E$17/G9 -> 5825.3794 | J9: =I9*H9 -> 1730.0294 | K9: =L9/Acquirer!$E$11 -> 0.90200552 | L9: =J9/Target!$E$15 -> 31.119191 | M9: =L9/Target!$E$11-1 -> -0.17674099 | O9: Revenue-based contribution flatters Calder least: it is the smaller but higher-margin business, so it contributes more EBITDA than revenue.
C10: Revenue -FY27E | D10: =Acquirer!H90 -> 7060.9885 | E10: =Target!H90 -> 3000.0668 | F10: =D10+E10 -> 10061.055 | G10: =D10/F10 -> 0.7018139 | H10: =E10/F10 -> 0.2981861 | I10: =Acquirer!$E$17/G10 -> 5835.3789 | J10: =I10*H10 -> 1740.0289 | K10: =L10/Acquirer!$E$11 -> 0.90721905 | L10: =J10/Target!$E$15 -> 31.299057 | M10: =L10/Target!$E$11-1 -> -0.17198261
C11: EBITDA -FY26E | D11: =Acquirer!G192 -> 675.99633 | E11: =Target!G192 -> 347.03477 | F11: =D11+E11 -> 1023.0311 | G11: =D11/F11 -> 0.66077788 | H11: =E11/F11 -> 0.33922212 | I11: =Acquirer!$E$17/G11 -> 6197.771 | J11: =I11*H11 -> 2102.421 | K11: =L11/Acquirer!$E$11 -> 1.0961636 | L11: =J11/Target!$E$15 -> 37.817646 | M11: =L11/Target!$E$11-1 -> 0.00046681692
C12: EBITDA -FY27E | D12: =Acquirer!H192 -> 717.57358 | E12: =Target!H192 -> 374.89005 | F12: =D12+E12 -> 1092.4636 | G12: =D12/F12 -> 0.65683979 | H12: =E12/F12 -> 0.34316021 | I12: =Acquirer!$E$17/G12 -> 6234.9299 | J12: =I12*H12 -> 2139.5799 | K12: =L12/Acquirer!$E$11 -> 1.1155376 | L12: =J12/Target!$E$15 -> 38.486047 | M12: =L12/Target!$E$11-1 -> 0.018149398
C13: EBIT -FY26E | D13: =Acquirer!G102 -> 568.57454 | E13: =Target!G102 -> 285.38785 | F13: =D13+E13 -> 853.96239 | G13: =D13/F13 -> 0.66580748 | H13: =E13/F13 -> 0.33419252 | I13: =Acquirer!$E$17/G13 -> 6150.9523 | J13: =I13*H13 -> 2055.6023 | K13: =L13/Acquirer!$E$11 -> 1.0717532 | L13: =J13/Target!$E$15 -> 36.975486 | M13: =L13/Target!$E$11-1 -> -0.021812541
C14: Net Income -FY26E | D14: =Acquirer!G108 -> 374.49697 | E14: =Target!G108 -> 199.45927 | F14: =D14+E14 -> 573.95624 | G14: =D14/F14 -> 0.65248349 | H14: =E14/F14 -> 0.34751651 | I14: =Acquirer!$E$17/G14 -> 6276.5573 | J14: =I14*H14 -> 2181.2073 | K14: =L14/Acquirer!$E$11 -> 1.1372414 | L14: =J14/Target!$E$15 -> 39.234828 | M14: =L14/Target!$E$11-1 -> 0.037958413
C15: Net Income -FY27E | D15: =Acquirer!H108 -> 413.69285 | E15: =Target!H108 -> 223.91831 | F15: =D15+E15 -> 637.61117 | G15: =D15/F15 -> 0.64881683 | H15: =E15/F15 -> 0.35118317 | I15: =Acquirer!$E$17/G15 -> 6312.028 | J15: =I15*H15 -> 2216.678 | K15: =L15/Acquirer!$E$11 -> 1.1557352 | L15: =J15/Target!$E$15 -> 39.872863 | M15: =L15/Target!$E$11-1 -> 0.054837649
C16: Total Assets at Close | D16: =Acquirer!F128 -> 4404.465 | E16: =Target!F128 -> 2141.374 | F16: =D16+E16 -> 6545.839 | G16: =D16/F16 -> 0.67286486 | H16: =E16/F16 -> 0.32713514 | I16: =Acquirer!$E$17/G16 -> 6086.4377 | J16: =I16*H16 -> 1991.0877 | K16: =L16/Acquirer!$E$11 -> 1.0381165 | L16: =J16/Target!$E$15 -> 35.815019 | M16: =L16/Target!$E$11-1 -> -0.052512726
