Workbook
Name COD: #REF!
Name COD: Inputs_TI!$F$5
Name Financial_Close: #REF!
Name Financial_Close: Inputs_TI!$F$4
Name Financial_End: Inputs_TI!$F$4

Sheet Model Notes
B2: Model Notes
C4: Purpose:
D5: This project finance model was independently completed by Prasad Lambor as a portfolio exercise using the publicly available Project Finance Modelling Test developed by the Renewables Valuation Institute (RVI)
D6: The model evaluates a hypothetical 150 MWp solar PV project with a 30-year power purchase agreement and assesses the project’s financial viability and investor returns
C8: Attribution:
D9: The case study assumptions and SOFR forward curve were provided as part of RVI’s publicly available modelling exercise
D10: The model structure, formulas, calculations, debt sizing, return analysis and presentation were completed independently by Prasad Lambor
C12: Model Scope:
D13: The model includes:
E14: Energy generation and revenue forecasts
E15: Operating expenditure projections
E16: Depreciation and taxation
E17: Debt sizing based on target DSCR
E18: Debt repayment and interest calculations
E19: Project and equity cash flows
E20: Project IRR and Equity IRR
E21: Net Present Value
E22: Cash-on-Cash yield and multiple
E23: Equity payback period
C25: Disclaimer:
D26: This model is provided solely for educational and portfolio purposes. It is based on a hypothetical project and should not be relied upon for investment, financing or commercial decisions

Sheet SOFR Forward Curve
B2: SOFR Forward Curve
C3: SOFR Forward Curve
C4: Floating Base Rate | E4: 2026 | F4: 2027 | G4: 2028 | H4: 2029 | I4: 2030 | J4: 2031 | K4: 2032 | L4: 2033 | M4: 2034 | N4: 2035 | O4: 2036 | P4: 2037 | Q4: 2038 | R4: 2039 | S4: 2040 | T4: 2041 | U4: 2042 | V4: 2043 | W4: 2044 | X4: 2045 | Y4: 2046 | Z4: 2047 | AA4: 2048 | AB4: 2049 | AC4: 2050 | AD4: 2051 | AE4: 2052 | AF4: 2053 | AG4: 2054 | AH4: 2055 | AI4: 2056 | AJ4: 2057 | AK4: 2058 | AL4: 2059 | AM4: 2060 | AN4: 2061 | AO4: 2062
C5: SOFR Forward Curve | D5: % | E5: 0.0351 | F5: 0.0336 | G5: 0.0354 | H5: 0.0368 | I5: 0.0386 | J5: 0.0402 | K5: 0.0413 | L5: 0.0422 | M5: 0.0432 | N5: 0.0442 | O5: 0.045 | P5: 0.0454 | Q5: 0.0454 | R5: 0.045 | S5: 0.0443 | T5: 0.0434 | U5: 0.0426 | V5: 0.0418 | W5: 0.0411 | X5: 0.0405 | Y5: 0.0399 | Z5: 0.0393 | AA5: 0.0388 | AB5: 0.0383 | AC5: 0.0379 | AD5: 0.0375 | AE5: 0.0371 | AF5: 0.0368 | AG5: 0.0365 | AH5: 0.0359 | AI5: 0.0357 | AJ5: 0.0355 | AK5: 0.0353 | AL5: 0.0351 | AM5: 0.035 | AN5: 0.0349 | AO5: 0.0348

Sheet Inputs_TI
B2: Inputs Time Independent
C3: Timing
D4: Financial Close | E4: Date | F4: 46022
D5: Commercial Operations Date (COD) | E5: Date | F5: 46023
D6: Project Lifetime | E6: Years | F6: 30
C8: Technical Parameters
D9: Installed Capacity | E9: MWp | F9: 150
D10: P50 Energy Yield | E10: MWh/MWp/p.a. | F10: 2100
D11: Total Energy Generation | E11: MWh/p.a. | F11: =F10*F9 -> 315000
D12: Degradation | E12: % p.a. | F12: 0.003
D13: Plant Availability | E13: % | F13: 0.99
C15: Revenue Assumptions – Power Purchase Agreement (PPA)
D16: Contract Term | E16: Years | F16: 30
D17: PPA Price | E17: $/MWh | F17: 75
D18: Price Escalation | E18: % p.a. | F18: 0.025
C20: Operating Expenditures
D21: O&M | E21: $/MWp p.a. | F21: 8000
D22: Insurance | E22: $/MWp p.a. | F22: 2000
D23: Other Opex | E23: $/MWp p.a. | F23: 10000
D24: Land Lease | E24: % of revenue | F24: 0.02
D25: Opex Escalation (CPI) | E25: % p.a. | F25: 0.02
C27: Capital Expenditures & Depreciation
D28: Total Cost (fully in place) | E28: $/MWp | F28: 1850000
D29: Depreciation Tenure (Straight line) | E29: Years | F29: 20
C31: Financing Assumptions
D32: Debt Sizing Parameters
D33: Maximum Leverage | E33: % | F33: 0.9
D34: Maximum Debt Tenor | E34: Years | F34: 20
D35: Target DSCR (P50) | E35: x | F35: 1.3
D37: Interest Rate Assumptions
D38: Debt Margin | E38: % | F38: 0.02
D39: Hedging Ratio | E39: % | F39: 0.75
D40: Fixed Swap Rate | E40: % | F40: 0.04
C42: Tax Assumptions
D43: Corporate Tax Rate | E43: % | F43: 0.25
C45: Return Expectations
D46: Target Minimum Equity IRR | E46: % | F46: 0.1

Sheet Inputs_TD
B2: SOFR Forward Curve
C3: SOFR Forward Curve
C4: Floating Base Rate | E4: 2026 | F4: 2027 | G4: 2028 | H4: 2029 | I4: 2030 | J4: 2031 | K4: 2032 | L4: 2033 | M4: 2034 | N4: 2035 | O4: 2036 | P4: 2037 | Q4: 2038 | R4: 2039 | S4: 2040 | T4: 2041 | U4: 2042 | V4: 2043 | W4: 2044 | X4: 2045 | Y4: 2046 | Z4: 2047 | AA4: 2048 | AB4: 2049 | AC4: 2050 | AD4: 2051 | AE4: 2052 | AF4: 2053 | AG4: 2054 | AH4: 2055 | AI4: 2056 | AJ4: 2057 | AK4: 2058 | AL4: 2059 | AM4: 2060 | AN4: 2061 | AO4: 2062
C5: SOFR Forward Curve | D5: % | E5: 0.0351 | F5: 0.0336 | G5: 0.0354 | H5: 0.0368 | I5: 0.0386 | J5: 0.0402 | K5: 0.0413 | L5: 0.0422 | M5: 0.0432 | N5: 0.0442 | O5: 0.045 | P5: 0.0454 | Q5: 0.0454 | R5: 0.045 | S5: 0.0443 | T5: 0.0434 | U5: 0.0426 | V5: 0.0418 | W5: 0.0411 | X5: 0.0405 | Y5: 0.0399 | Z5: 0.0393 | AA5: 0.0388 | AB5: 0.0383 | AC5: 0.0379 | AD5: 0.0375 | AE5: 0.0371 | AF5: 0.0368 | AG5: 0.0365 | AH5: 0.0359 | AI5: 0.0357 | AJ5: 0.0355 | AK5: 0.0353 | AL5: 0.0351 | AM5: 0.035 | AN5: 0.0349 | AO5: 0.0348

Sheet Calculations
B2: Basic Project Finance Model
C3: Model timeline & Flags
D4: Year | K4: =YEAR(K6) -> 2025 | L4: =YEAR(L6) -> 2026 | M4: =YEAR(M6) -> 2027 | N4: =YEAR(N6) -> 2028 | O4: =YEAR(O6) -> 2029 | P4: =YEAR(P6) -> 2030 | Q4: =YEAR(Q6) -> 2031 | R4: =YEAR(R6) -> 2032 | ... AT4: =YEAR(AT6) -> 2060
D5: Start of Period | L5: =K6+1 -> 46023 | M5: =L6+1 -> 46388 | N5: =M6+1 -> 46753 | O5: =N6+1 -> 47119 | P5: =O6+1 -> 47484 | Q5: =P6+1 -> 47849 | R5: =Q6+1 -> 48214 | S5: =R6+1 -> 48580 | ... AT5: =AS6+1 -> 58441
D6: End of Period | K6: =Financial_Close -> 46022 | L6: =EOMONTH(L5,12-1) -> 46387 | M6: =EOMONTH(M5,12-1) -> 46752 | N6: =EOMONTH(N5,12-1) -> 47118 | O6: =EOMONTH(O5,12-1) -> 47483 | P6: =EOMONTH(P5,12-1) -> 47848 | Q6: =EOMONTH(Q5,12-1) -> 48213 | R6: =EOMONTH(R5,12-1) -> 48579 | S6: =EOMONTH(S5,12-1) -> 48944 | ... AT6: =EOMONTH(AT5,12-1) -> 58806
D8: Flags | G8: Start | H8: End
D9: Financial Close | E9: [1,0] | H9: =Financial_Close -> 46022 | J9: =SUM(K9:AT9) -> 1 | K9: =IF($H$9=K6, 1, 0) -> 1 | L9: =IF($H$9=L6, 1, 0) -> 0 | M9: =IF($H$9=M6, 1, 0) -> 0 | N9: =IF($H$9=N6, 1, 0) -> 0 | O9: =IF($H$9=O6, 1, 0) -> 0 | P9: =IF($H$9=P6, 1, 0) -> 0 | Q9: =IF($H$9=Q6, 1, 0) -> 0 | R9: =IF($H$9=R6, 1, 0) -> 0 | ... AT9: =IF($H$9=AT6, 1, 0) -> 0
D10: Operations | E10: [1,0] | G10: =COD -> 46023 | H10: =EOMONTH(Calculations!G10,Inputs_TI!F6*12-1) -> 56979 | J10: =SUM(K10:AT10) -> 30 | K10: =IF(AND(K$5>=$G10, K$6<=$H10), 1,0) -> 0 | L10: =IF(AND(L$5>=$G10, L$6<=$H10), 1,0) -> 1 | M10: =IF(AND(M$5>=$G10, M$6<=$H10), 1,0) -> 1 | N10: =IF(AND(N$5>=$G10, N$6<=$H10), 1,0) -> 1 | O10: =IF(AND(O$5>=$G10, O$6<=$H10), 1,0) -> 1 | P10: =IF(AND(P$5>=$G10, P$6<=$H10), 1,0) -> 1 | Q10: =IF(AND(Q$5>=$G10, Q$6<=$H10), 1,0) -> 1 | R10: =IF(AND(R$5>=$G10, R$6<=$H10), 1,0) -> 1 | ... AT10: =IF(AND(AT$5>=$G10, AT$6<=$H10), 1,0) -> 0
D11: PPA Term | E11: [1,0] | G11: =COD -> 46023 | H11: =EOMONTH(Calculations!G11,Inputs_TI!F16*12-1) -> 56979 | J11: =SUM(K11:AT11) -> 30 | K11: =IF(AND(K$5>=$G11, K$6<=$H11), 1,0) -> 0 | L11: =IF(AND(L$5>=$G11, L$6<=$H11), 1,0) -> 1 | M11: =IF(AND(M$5>=$G11, M$6<=$H11), 1,0) -> 1 | N11: =IF(AND(N$5>=$G11, N$6<=$H11), 1,0) -> 1 | O11: =IF(AND(O$5>=$G11, O$6<=$H11), 1,0) -> 1 | P11: =IF(AND(P$5>=$G11, P$6<=$H11), 1,0) -> 1 | Q11: =IF(AND(Q$5>=$G11, Q$6<=$H11), 1,0) -> 1 | R11: =IF(AND(R$5>=$G11, R$6<=$H11), 1,0) -> 1 | ... AT11: =IF(AND(AT$5>=$G11, AT$6<=$H11), 1,0) -> 0
D12: Depreciation | E12: [1,0] | G12: =COD -> 46023 | H12: =EOMONTH(Calculations!G12,Inputs_TI!F29*12-1) -> 53327 | J12: =SUM(K12:AT12) -> 20 | K12: =IF(AND(K$5>=$G12, K$6<=$H12), 1,0) -> 0 | L12: =IF(AND(L$5>=$G12, L$6<=$H12), 1,0) -> 1 | M12: =IF(AND(M$5>=$G12, M$6<=$H12), 1,0) -> 1 | N12: =IF(AND(N$5>=$G12, N$6<=$H12), 1,0) -> 1 | O12: =IF(AND(O$5>=$G12, O$6<=$H12), 1,0) -> 1 | P12: =IF(AND(P$5>=$G12, P$6<=$H12), 1,0) -> 1 | Q12: =IF(AND(Q$5>=$G12, Q$6<=$H12), 1,0) -> 1 | R12: =IF(AND(R$5>=$G12, R$6<=$H12), 1,0) -> 1 | ... AT12: =IF(AND(AT$5>=$G12, AT$6<=$H12), 1,0) -> 0
D13: Debt Tenor | E13: [1,0] | G13: =COD -> 46023 | H13: =EOMONTH(Calculations!G13,Inputs_TI!F34*12-1) -> 53327 | J13: =SUM(K13:AT13) -> 20 | K13: =IF(AND(K$5>=$G13, K$6<=$H13), 1,0) -> 0 | L13: =IF(AND(L$5>=$G13, L$6<=$H13), 1,0) -> 1 | M13: =IF(AND(M$5>=$G13, M$6<=$H13), 1,0) -> 1 | N13: =IF(AND(N$5>=$G13, N$6<=$H13), 1,0) -> 1 | O13: =IF(AND(O$5>=$G13, O$6<=$H13), 1,0) -> 1 | P13: =IF(AND(P$5>=$G13, P$6<=$H13), 1,0) -> 1 | Q13: =IF(AND(Q$5>=$G13, Q$6<=$H13), 1,0) -> 1 | R13: =IF(AND(R$5>=$G13, R$6<=$H13), 1,0) -> 1 | ... AT13: =IF(AND(AT$5>=$G13, AT$6<=$H13), 1,0) -> 0
C15: Inflation
D16: PPA Escalation | E16: Index | G16: =Inputs_TI!F18 -> 0.025 | K16: 1 | L16: =K16*(1+$G16) -> 1.025 | M16: =L16*(1+$G16) -> 1.050625 | N16: =M16*(1+$G16) -> 1.0768906 | O16: =N16*(1+$G16) -> 1.1038129 | P16: =O16*(1+$G16) -> 1.1314082 | Q16: =P16*(1+$G16) -> 1.1596934 | R16: =Q16*(1+$G16) -> 1.1886858 | S16: =R16*(1+$G16) -> 1.2184029 | ... AT16: =AS16*(1+$G16) -> 2.3732052
D17: Opex Escalation | E17: Index | G17: =Inputs_TI!F25 -> 0.02 | K17: 1 | L17: =K17*(1+$G17) -> 1.02 | M17: =L17*(1+$G17) -> 1.0404 | N17: =M17*(1+$G17) -> 1.061208 | O17: =N17*(1+$G17) -> 1.0824322 | P17: =O17*(1+$G17) -> 1.1040808 | Q17: =P17*(1+$G17) -> 1.1261624 | R17: =Q17*(1+$G17) -> 1.1486857 | S17: =R17*(1+$G17) -> 1.1716594 | ... AT17: =AS17*(1+$G17) -> 1.9998896
C19: Generation
G20: P50 | H20: Availability
D21: Net generation before degradation | E21: MWh | G21: =Inputs_TI!F11 -> 315000 | H21: =Inputs_TI!F13 -> 0.99 | J21: =SUM(K21:AT21) -> 9355500 | K21: =$G21*$H21*K10 -> 0 | L21: =$G21*$H21*L10 -> 311850 | M21: =$G21*$H21*M10 -> 311850 | N21: =$G21*$H21*N10 -> 311850 | O21: =$G21*$H21*O10 -> 311850 | P21: =$G21*$H21*P10 -> 311850 | Q21: =$G21*$H21*Q10 -> 311850 | R21: =$G21*$H21*R10 -> 311850 | ... AT21: =$G21*$H21*AT10 -> 0
D22: Degradation | E22: % | G22: =Inputs_TI!F12 -> 0.003 | K22: 1 | L22: =K22*(1-$G22)*L10 -> 0.997 | M22: =L22*(1-$G22) -> 0.994009 | N22: =M22*(1-$G22) -> 0.99102697 | O22: =N22*(1-$G22) -> 0.98805389 | P22: =O22*(1-$G22) -> 0.98508973 | Q22: =P22*(1-$G22) -> 0.98213446 | R22: =Q22*(1-$G22) -> 0.97918806 | S22: =R22*(1-$G22) -> 0.97625049 | T22: =S22*(1-$G22) -> 0.97332174 | ... AT22: =AS22*(1-$G22) -> 0.90018245
D23: Net generation after degradation | E23: MWh | J23: =SUM(K23:AT23) -> 8932824.4 | L23: =L21*L22 -> 310914.45 | M23: =M21*M22 -> 309981.71 | N23: =N21*N22 -> 309051.76 | O23: =O21*O22 -> 308124.61 | P23: =P21*P22 -> 307200.23 | Q23: =Q21*Q22 -> 306278.63 | R23: =R21*R22 -> 305359.8 | S23: =S21*S22 -> 304443.72 | ... AT23: =AT21*AT22 -> 0
C25: Capex, Revenue & Opex
D26: Capital Expenditure | G26: $/MWp | H26: MW
D27: Total Cost (fully in place) | E27: $ | G27: =Inputs_TI!F28 -> 1850000 | H27: =Inputs_TI!F9 -> 150 | J27: =SUM(K27:AT27) -> 277500000 | K27: =$G27*$H27*K9 -> 277500000 | L27: =$G27*$H27*L9 -> 0 | M27: =$G27*$H27*M9 -> 0 | N27: =$G27*$H27*N9 -> 0 | O27: =$G27*$H27*O9 -> 0 | P27: =$G27*$H27*P9 -> 0 | Q27: =$G27*$H27*Q9 -> 0 | R27: =$G27*$H27*R9 -> 0 | ... AT27: =$G27*$H27*AT9 -> 0
D29: Revenues | G29: $/MWh
D30: PPA Revenue | E30: $ | G30: =Inputs_TI!F17 -> 75 | J30: =SUM(K30:AT30) -> 9.9942062e+08 | K30: =K23*$G$30*K11*K16 -> 0 | L30: =L23*$G$30*L11*L16 -> 23901548 | M30: =M23*$G$30*M11*M16 -> 24425590 | N30: =N23*$G$30*N11*N16 -> 24961121 | O30: =O23*$G$30*O11*O16 -> 25508393 | P30: =P23*$G$30*P11*P16 -> 26067665 | Q30: =Q23*$G$30*Q11*Q16 -> 26639199 | R30: =R23*$G$30*R11*R16 -> 27223263 | ... AT30: =AT23*$G$30*AT11*AT16 -> 0
D31: Total Revenue | E31: $ | J31: =SUM(K31:AT31) -> 9.9942062e+08 | K31: =SUM(K30) -> 0 | L31: =SUM(L30) -> 23901548 | M31: =SUM(M30) -> 24425590 | N31: =SUM(N30) -> 24961121 | O31: =SUM(O30) -> 25508393 | P31: =SUM(P30) -> 26067665 | Q31: =SUM(Q30) -> 26639199 | R31: =SUM(R30) -> 27223263 | ... AT31: =SUM(AT30) -> 0
D33: Operational Expenditure
D34: =Inputs_TI!D21 -> O&M | E34: $ | G34: =Inputs_TI!F21 -> 8000 | H34: $/MWp p.a. | J34: =SUM(K34:AT34) -> 49655329 | K34: =$G34*$H$27*K$17*K$10 -> 0 | L34: =$G34*$H$27*L$17*L$10 -> 1224000 | M34: =$G34*$H$27*M$17*M$10 -> 1248480 | N34: =$G34*$H$27*N$17*N$10 -> 1273449.6 | O34: =$G34*$H$27*O$17*O$10 -> 1298918.6 | P34: =$G34*$H$27*P$17*P$10 -> 1324897 | Q34: =$G34*$H$27*Q$17*Q$10 -> 1351394.9 | R34: =$G34*$H$27*R$17*R$10 -> 1378422.8 | ... AT34: =$G34*$H$27*AT$17*AT$10 -> 0
D35: =Inputs_TI!D22 -> Insurance | E35: $ | G35: =Inputs_TI!F22 -> 2000 | H35: $/MWp p.a. | J35: =SUM(K35:AT35) -> 12413832 | K35: =$G35*$H$27*K$17*K$10 -> 0 | L35: =$G35*$H$27*L$17*L$10 -> 306000 | M35: =$G35*$H$27*M$17*M$10 -> 312120 | N35: =$G35*$H$27*N$17*N$10 -> 318362.4 | O35: =$G35*$H$27*O$17*O$10 -> 324729.65 | P35: =$G35*$H$27*P$17*P$10 -> 331224.24 | Q35: =$G35*$H$27*Q$17*Q$10 -> 337848.73 | R35: =$G35*$H$27*R$17*R$10 -> 344605.7 | ... AT35: =$G35*$H$27*AT$17*AT$10 -> 0
D36: =Inputs_TI!D23 -> Other Opex | E36: $ | G36: =Inputs_TI!F23 -> 10000 | H36: $/MWp p.a. | J36: =SUM(K36:AT36) -> 62069161 | K36: =$G36*$H$27*K$17*K$10 -> 0 | L36: =$G36*$H$27*L$17*L$10 -> 1530000 | M36: =$G36*$H$27*M$17*M$10 -> 1560600 | N36: =$G36*$H$27*N$17*N$10 -> 1591812 | O36: =$G36*$H$27*O$17*O$10 -> 1623648.2 | P36: =$G36*$H$27*P$17*P$10 -> 1656121.2 | Q36: =$G36*$H$27*Q$17*Q$10 -> 1689243.6 | R36: =$G36*$H$27*R$17*R$10 -> 1723028.5 | ... AT36: =$G36*$H$27*AT$17*AT$10 -> 0
D37: =Inputs_TI!D24 -> Land Lease | E37: $ | G37: =Inputs_TI!F24 -> 0.02 | H37: % of Revenue | J37: =SUM(K37:AT37) -> 19988412 | K37: =$G37*K31 -> 0 | L37: =$G37*L31 -> 478030.97 | M37: =$G37*M31 -> 488511.8 | N37: =$G37*N31 -> 499222.42 | O37: =$G37*O31 -> 510167.87 | P37: =$G37*P31 -> 521353.3 | Q37: =$G37*Q31 -> 532783.97 | R37: =$G37*R31 -> 544465.26 | ... AT37: =$G37*AT31 -> 0
D38: Total Opex | J38: =SUM(J34:J37) -> 1.4412673e+08 | K38: =SUM(K34:K37) -> 0 | L38: =SUM(L34:L37) -> 3538031 | M38: =SUM(M34:M37) -> 3609711.8 | N38: =SUM(N34:N37) -> 3682846.4 | O38: =SUM(O34:O37) -> 3757464.3 | P38: =SUM(P34:P37) -> 3833595.7 | Q38: =SUM(Q34:Q37) -> 3911271.2 | ... AT38: =SUM(AT34:AT37) -> 0
D40: EBITDA | E40: $ | J40: =SUM(K40:AT40) -> 8.5529389e+08 | K40: =K31- K38 -> 0 | L40: =L31- L38 -> 20363517 | M40: =M31- M38 -> 20815878 | N40: =N31- N38 -> 21278274 | O40: =O31- O38 -> 21750929 | P40: =P31- P38 -> 22234069 | Q40: =Q31- Q38 -> 22727927 | R40: =R31- R38 -> 23232741 | ... AT40: =AT31- AT38 -> 0
D42: Pre-tax Cash Flow | E42: $ | J42: =SUM(K42:AT42) -> 5.7779389e+08 | K42: =-K27+K40 -> -277500000 | L42: =-L27+L40 -> 20363517 | M42: =-M27+M40 -> 20815878 | N42: =-N27+N40 -> 21278274 | O42: =-O27+O40 -> 21750929 | P42: =-P27+P40 -> 22234069 | Q42: =-Q27+Q40 -> 22727927 | R42: =-R27+R40 -> 23232741 | ... AT42: =-AT27+AT40 -> 0
D44: Unlevered pre-tax Project IRR | E44: % p.a. | G44: =XIRR(K42:AT42,$K$6:$AT$6) -> 0.082350984
C46: Depreciation & Unlevered Taxes
D47: Tax Depreciation | G47: Tax Basis
D48: Depreciation | E48: $ | G48: =J27 -> 277500000 | J48: =SUM(K48:AT48) -> -277500000 | K48: =-$G$48/$J$12*K12 -> 0 | L48: =-$G$48/$J$12*L12 -> -13875000 | M48: =-$G$48/$J$12*M12 -> -13875000 | N48: =-$G$48/$J$12*N12 -> -13875000 | O48: =-$G$48/$J$12*O12 -> -13875000 | P48: =-$G$48/$J$12*P12 -> -13875000 | Q48: =-$G$48/$J$12*Q12 -> -13875000 | R48: =-$G$48/$J$12*R12 -> -13875000 | ... AT48: =-$G$48/$J$12*AT12 -> 0
D50: EBIT | E50: $ | J50: =SUM(K50:AT50) -> 5.7779389e+08 | K50: =K40+K48 -> 0 | L50: =L40+L48 -> 6488517.4 | M50: =M40+M48 -> 6940878 | N50: =N40+N48 -> 7403274.4 | O50: =O40+O48 -> 7875929.1 | P50: =P40+P48 -> 8359069.2 | Q50: =Q40+Q48 -> 8852927.3 | R50: =R40+R48 -> 9357740.7 | ... AT50: =AT40+AT48 -> 0
D52: Less: Unlevered Taxes | E52: $ | G52: =Inputs_TI!F43 -> 0.25 | J52: =SUM(K52:AT52) -> -1.4444847e+08 | K52: =-$G$52*K50 -> 0 | L52: =-$G$52*L50 -> -1622129.3 | M52: =-$G$52*M50 -> -1735219.5 | N52: =-$G$52*N50 -> -1850818.6 | O52: =-$G$52*O50 -> -1968982.3 | P52: =-$G$52*P50 -> -2089767.3 | Q52: =-$G$52*Q50 -> -2213231.8 | R52: =-$G$52*R50 -> -2339435.2 | ... AT52: =-$G$52*AT50 -> 0
D54: After-tax Cash Flow | E54: $ | J54: =SUM(K54:AT54) -> 4.3334541e+08 | K54: =K42+K52 -> -277500000 | L54: =L42+L52 -> 18741388 | M54: =M42+M52 -> 19080658 | N54: =N42+N52 -> 19427456 | O54: =O42+O52 -> 19781947 | P54: =P42+P52 -> 20144302 | Q54: =Q42+Q52 -> 20514695 | R54: =R42+R52 -> 20893306 | ... AT54: =AT42+AT52 -> 0
...

Sheet Output
B2: Case Study Output Summary
C3: Summary of Key outputs on a P50 Basis
C5: Internal Rate of Return (IRR)
C6: Unlevered pre-tax Project IRR | D6: % p.a. | E6: =Calculations!G44 -> 0.082350984
C7: Unlevered after-tax Project IRR | D7: % p.a. | E7: =Calculations!G56 -> 0.069184342
C8: Levered Equity IRR | D8: % p.a. | E8: =Calculations!G107 -> 0.10526181
C9: =Inputs_TI!D46 -> Target Minimum Equity IRR | D9: % p.a. | E9: =Inputs_TI!F46 -> 0.1
C11: Other Metrics
C12: Net Present Value (NPV) | D12: $ | E12: =Calculations!G111 -> 4324684.2
C13: Cash-on-Cash Yield | D13: % p.a. | E13: =AVERAGE(Calculations!L114:AO114) -> 0.19041785
C14: CoC Multiple | D14: x | E14: =Calculations!G114 -> 5.7125356
C15: Equity Payback Period | D15: Years | E15: =Calculations!G117 -> 13
