Workbook

Sheet Cover
B2: COLLINS FOODS LIMITED (ASX: CKF)
B3: Discounted Cash Flow Valuation — FY27E to FY35E
B5: Prepared by | C5: Prasad Lambor
B6: Valuation date | C6: 8 August 2026
B7: Base year | C7: FY26A — 53 weeks ended 3 May 2026
B8: Currency | C8: A$ millions unless stated
B9: Primary source | C9: CKF FY26 Results Presentation, released 30 June 2026
B11: PURPOSE
B12: An enterprise discounted cash flow of Collins Foods, built bottom-up from restaurant count and average unit volume for each of the three operating geographies. Designed to be interrogated: every assumption sits in a labelled cell with its source, and the two lease-accounting treatments are computed in parallel and reconciled.
B17: COLOUR CONVENTION
B18: Blue text | C18: Hardcoded input or scenario lever — this is what you change
B19: Black text | C19: Formula calculated on this sheet — do not overwrite
B20: Green text | C20: Link to another sheet in this workbook
B21: Yellow fill | C21: Key assumption or a cell needing your judgement or market data
B22: Red text | C22: Warning or a figure requiring verification
B24: SHEET INDEX
B25: Control | C25: Switches, valuation summary and integrity checks. Start here.
B26: Assumptions | C26: Every forecast driver, as three scenario blocks plus the live selected case.
B27: Historicals | C27: FY23A–FY26A reported actuals, with the source of every figure and the AASB 16 bridge.
B28: Model | C28: The engine: drivers to revenue to EBITDA to EBIT to NOPAT to free cash flow, on both lease bases.
B29: WACC | C29: Cost of equity, cost of debt and capital structure — one WACC per lease basis.
B30: DCF | C30: Discounting, terminal value, enterprise value, equity bridge and the pre/post reconciliation.
B31: Sensitivity | C31: Live WACC versus growth and WACC versus exit multiple grids.
B32: Comps | C32: Trading comparables template and football field. Market data to be populated.
B33: Notes & Audit | C33: Source mapping for every hardcoded number, and the reasoning behind each convention.
B36: IMPORTANT | C36: Educational and illustrative only. Not investment advice and not a professional valuation. Forecasts are the author's own and are not company guidance.

Sheet Control
B2: CONTROL PANEL
C3: Change the switches and the whole model re-runs. Start here.
C5: SWITCHES
C6: Switch | D6: Setting | E6: Reads as | F6: Options
C7: Scenario | D7: 3 | E7: =CHOOSE($D$7,"Base","Upside","Downside") -> Downside | F7: 1 = Base | 2 = Upside | 3 = Downside
C8: Kwench by KFC initiative | D8: 1 | E8: =CHOOSE($D$8,"Included","Excluded") -> Included | F8: 1 = Include the uplift | 2 = Strip it out, to isolate what the initiative is worth
C9: Terminal value method | D9: 1 | E9: =CHOOSE($D$9,"Gordon growth","Exit multiple") -> Gordon growth | F9: 1 = Gordon growth perpetuity | 2 = Exit EV/EBITDA multiple
C10: Discounting convention | D10: 1 | E10: =CHOOSE($D$10,"Mid-year","Year-end") -> Mid-year | F10: 1 = Mid-year | 2 = Year-end
C12: VALUATION SUMMARY
C13: Output | D13: Value | F13: Comment
C14: Enterprise value (A$m) | D14: =DCF!E41 -> 955.51948 | F14: PV of forecast cash flows plus PV of terminal value
C15: Net debt deducted (A$m) | D15: =DCF!E44 -> -119.6 | F15: Includes lease liabilities only on a post-AASB 16 basis
C16: Equity value (A$m) | D16: =DCF!E45 -> 835.91948 | F16: Enterprise value less net debt
C17: Shares on issue (m) | D17: =DCF!E46 -> 118.07692 | F17: Underlying NPAT divided by reported basic EPS
C18: Value per share (A$) | D18: =DCF!E47 -> 7.0794483 | F18: The headline output
C19: Current share price (A$) | D19: =DCF!E48 -> 8.24 | F19: Early August 2026
C20: Premium / (discount) to market | D20: =DCF!E49 -> -0.14084365 | F20: Positive means the model says CKF is undervalued
C21: Implied FY27E EV/EBITDA | D21: =DCF!E52 -> 5.942252 | F21: Sense-check against the trading comparables
C22: Terminal value as % of EV | D22: =DCF!E53 -> 0.58249958 | F22: How much of the answer is the perpetuity assumption
C24: INTEGRITY CHECKS
C25: Check | D25: Result | E25: Status | F25: What it proves
C26: FY26A modelled revenue less reported | D26: =Model!E40-Historicals!H6 -> 0 | E26: =IF(ABS(D26)<0.5,"OK","CHECK") -> OK | F26: The driver build reproduces the actual year — the wiring is right
C27: FY26A modelled EBITDA less reported | D27: =Model!E45-Historicals!H7 -> 0.0009 | E27: =IF(ABS(D27)<0.5,"OK","CHECK") -> OK | F27: Margin and cost assumptions rebuild reported EBITDA
C28: Segment revenue sums to group | D28: =Model!E40-Model!E12-Model!E34 -> 0 | E28: =IF(ABS(D28)<0.1,"OK","CHECK") -> OK | F28: No segment double-counted or dropped
C29: AASB 16 bridge closes | D29: =Historicals!H69 -> 6.9988599 | E29: =IF(AND(D29>0,D29<15),"OK","CHECK") -> OK | F29: Rent, ROU depreciation and lease interest reconcile between the two bases
C30: Scenario switch in valid range | D30: =D7 -> 3 | E30: =IF(AND(D30>=1,D30<=3),"OK","CHECK") -> OK | F30: CHOOSE() returns an error outside 1 to 3
C31: WACC less terminal growth | D31: =DCF!E9-DCF!E17 -> 0.074350867 | E31: =IF(D31>0.005,"OK","CHECK") -> OK | F31: Gordon growth explodes as growth approaches WACC
C32: FY27E capex versus $80-100m guidance | D32: =Model!F61 -> 86.644204 | E32: =IF($D$7<>1,"n/a",IF(AND(D32>=75,D32<=105),"OK","CHECK")) -> n/a | F32: Base case only — the Upside deliberately builds more restaurants than guidance, so it should spend more
C33: Terminal value share of EV | D33: =DCF!E53 -> 0.58249958 | E33: =IF(D33<0.75,"OK",IF(D33<0.85,"NOTE","HIGH")) -> OK | F33: NOTE is normal for a stable business on a 5-year horizon; validate it with the implied exit multiple below
C34: Lease liabilities excluded from bridge | D34: =DCF!E43 -> 0 | E34: =IF(D34=0,"OK","CHECK") -> OK | F34: Must be zero, because rent is still an operating cost in the cash flows
C35: Implied Gordon exit multiple is sane | D35: =DCF!E37 -> 6.2388065 | E35: =IF(AND(D35>3,D35<14),"OK","CHECK") -> OK | F35: A Gordon terminal value implying a wild multiple means bad inputs
C36: Europe split sums to reported revenue | D36: =Historicals!H46 -> 0 | E36: =IF(ABS(D36)<0.1,"OK","CHECK") -> OK | F36: Germany and Netherlands are solved independently, so this is a real cross-check
C37: FY26A D&A per roll-forward vs reported | D37: ='Capex & PPE'!E51+(Historicals!H14-Historicals!H67) -> 0 | E37: =IF(ABS(D37)<0.1,"OK","CHECK") -> OK | F37: The fixed asset roll-forward reproduces reported depreciation and amortisation
C38: FY26A closing gross debt vs reported | D38: ='Debt & Leases'!E17-Historicals!H52 -> 0 | E38: =IF(ABS(D38)<0.1,"OK","CHECK") -> OK | F38: Debt schedule anchors to the reported balance sheet
C39: FY26A closing lease liability vs reported | D39: ='Debt & Leases'!E42-Historicals!H54 -> 0 | E39: =IF(ABS(D39)<0.1,"OK","CHECK") -> OK | F39: Lease roll-forward anchors to the reported balance sheet
C40: Cash never falls below the minimum | D40: =MIN('Debt & Leases'!F28:N28)-'Debt & Leases'!E10 -> 0 | E40: =IF(D40>=-0.1,"OK","CHECK") -> OK | F40: The plan is fundable — no year requires cash the company does not have
C41: Covenant never breached | D41: =MAX('Debt & Leases'!F33:N33) -> 1.0849832 | E41: =IF(D41<'Debt & Leases'!E11,"OK","BREACH") -> OK | F41: Net leverage stays inside the covenant across the forecast

Sheet Assumptions
B2: FORECAST ASSUMPTIONS
C5: BASE CASE
C6: Driver | D6: Unit | E6: FY27E | F6: FY28E | G6: FY29E | H6: FY30E | I6: FY31E | J6: FY32E | K6: FY33E | L6: FY34E | M6: FY35E | O6: Basis and source
C7: KFC AUSTRALIA
C8: Net new restaurants | D8: no. | E8: 8 | F8: 8 | G8: 8 | H8: 8 | I8: 8 | J8: 7 | K8: 6 | L8: 5 | M8: 4 | O8: Management guides 7-10 new Australian restaurants in FY27 (p.35). FY26 actual: 8 opened, 1 closed, 1 relocated.
C9: Same store sales growth | D9: % | E9: 0.035 | F9: 0.03 | G9: 0.0275 | H9: 0.025 | I9: 0.025 | J9: 0.025 | K9: 0.025 | L9: 0.025 | M9: 0.025 | O9: FY26 actual +2.7%. First 8 weeks of FY27 running at +4.0% (p.35). Base fades toward long-run food inflation plus modest traffic growth.
C10: Kwench incremental sales uplift | D10: % | E10: 0.015 | F10: 0.01 | G10: 0.0025 | H10: 0 | I10: 0 | J10: 0 | K10: 0 | L10: 0 | M10: 0 | O10: Management cites an initial 2-3% sales increase, with 80% of the network rolled out by April 2027 and 100% by mid-2027 (p.31). Applied on top of same store sales and phased over the rollout.
C11: Restaurant-level EBITDA margin | D11: % | E11: 0.21 | F11: 0.21 | G11: 0.211 | H11: 0.211 | I11: 0.212 | J11: 0.212 | K11: 0.212 | L11: 0.212 | M11: 0.212 | O11: FY26 actual 21.0%, down 26bps on delivery channel mix and value investment. Base assumes stabilisation; downside assumes Australian labour inflation is not offset by productivity.
C12: Segment G&A as % of revenue | D12: % | E12: 0.0195 | F12: 0.0195 | G12: 0.0192 | H12: 0.019 | I12: 0.019 | J12: 0.019 | K12: 0.019 | L12: 0.019 | M12: 0.019 | O12: FY26 actual 1.88% (restaurant EBITDA $260.5m less segment EBITDA $237.1m = $23.4m). Steps up in FY27 for the $2m+ training investment flagged on p.28.
C13: KFC GERMANY
C14: Net new restaurants | D14: no. | E14: 15 | F14: 10 | G14: 13 | H14: 16 | I14: 16 | J14: 10 | K14: 7 | L14: 5 | M14: 3 | O14: Base follows management's base-case network chart (p.33): 25 restaurants at FY26 post-Munich, then 32 / 42 / 55 / 71 through FY30. Upside follows the upper range 36 / 58 / 86 / 115. FY27 includes the 8 acquired Munich restaurants.
C15: of which acquired rather than built | D15: no. | E15: 8 | F15: 0 | G15: 0 | H15: 0 | I15: 0 | J15: 0 | K15: 0 | L15: 0 | M15: 0 | O15: The Munich acquisition of 8 restaurants completed 1 June 2026. These are bought, not built, so they must be excluded from new-restaurant capex and charged instead as acquisition consideration — otherwise the model double-counts the cost of the same 8 restaurants.
C16: Same store sales growth | D16: % | E16: -0.02 | F16: 0.02 | G16: 0.025 | H16: 0.025 | I16: 0.025 | J16: 0.025 | K16: 0.025 | L16: 0.025 | M16: 0.025 | O16: FY26 actual +3.7%. First 8 weeks of FY27 at -7.2% on a prolonged heatwave, weaker limited-time offers and soft consumer confidence (p.35). Base assumes a part-year drag then recovery.
C17: KFC NETHERLANDS
C18: Net new restaurants | D18: no. | E18: 1 | F18: 1 | G18: 1 | H18: 1 | I18: 1 | J18: 1 | K18: 1 | L18: 0 | M18: 0 | O18: A mature network — FY26 added one net restaurant. No expansion programme is disclosed.
C19: Same store sales growth | D19: % | E19: -0.03 | F19: 0.01 | G19: 0.015 | H19: 0.02 | I19: 0.02 | J19: 0.02 | K19: 0.02 | L19: 0.02 | M19: 0.02 | O19: FY26 actual 0.0%. First 8 weeks of FY27 at -7.8% (p.35). The Corporate Franchise Agreement has been extended to 31 December 2029 and Yum! resumes marketing responsibility from 1 January 2027 (p.23).
C20: KFC EUROPE — SHARED
C21: Restaurant-level EBITDA margin | D21: % | E21: 0.19 | F21: 0.193 | G21: 0.195 | H21: 0.198 | I21: 0.2 | J21: 0.201 | K21: 0.202 | L21: 0.202 | M21: 0.202 | O21: FY26 actual 19.3%, down 53bps on avian-influenza poultry costs which management expects to dissipate over FY27 (p.35). Modelled at the Europe level because CKF does not disclose margin by country.
C22: Segment G&A as % of revenue | D22: % | E22: 0.069 | F22: 0.067 | G22: 0.065 | H22: 0.063 | I22: 0.062 | J22: 0.06 | K22: 0.058 | L22: 0.057 | M22: 0.056 | O22: FY26 actual 6.52% (restaurant EBITDA $67.8m less segment EBITDA $44.9m = $22.9m). FY27 absorbs the $3m incremental German G&A investment flagged on p.33, then leverages as the network scales.
C23: GROUP COSTS, CAPITAL AND WORKING CAPITAL
C24: Unallocated corporate costs as % of revenue | D24: % | E24: 0.0235 | F24: 0.0235 | G24: 0.0233 | H24: 0.023 | I24: 0.023 | J24: 0.0228 | K24: 0.0226 | L24: 0.0225 | M24: 0.0225 | O24: FY26 actual 2.35%: segment EBITDA of $237.1m + $44.9m = $282.0m less reported group EBITDA of $244.5m = $37.5m. Not separately disclosed — derived as the residual.
C25: Rent expense as % of revenue | D25: % | E25: 0.0526 | F25: 0.0526 | G25: 0.0526 | H25: 0.0526 | I25: 0.0526 | J25: 0.0526 | K25: 0.0526 | L25: 0.0526 | M25: 0.0526 | O25: FY26 implied 5.26% ($83.7m of rent, being post-AASB 16 EBITDA less pre-AASB 16 EBITDA). Only used on the pre-AASB 16 basis.
C26: Maintenance and remodel capex as % of revenue | D26: % | E26: 0.019 | F26: 0.021 | G26: 0.022 | H26: 0.022 | I26: 0.022 | J26: 0.022 | K26: 0.022 | L26: 0.022 | M26: 0.022 | O26: FY26 actual: $15.3m asset capital maintenance + $16.8m remodels + $6.0m digital and sustainability = $38.1m, or 2.39% of revenue (p.9). FY27 is lower because spend is diverted to Kwench.
C27: Kwench and other project capex | D27: A$m | E27: 35 | F27: 10 | G27: 0 | H27: 0 | I27: 0 | J27: 0 | K27: 0 | L27: 0 | M27: 0 | O27: Management guides Kwench capex of $35m in FY27 and $10m in FY28 (p.31). Modelled as discrete project spend rather than a percentage of revenue.
C28: New restaurant capex — Australia | D28: A$m/store | E28: 1.8 | F28: 1.85 | G28: 1.9 | H28: 1.95 | I28: 2 | J28: 2.05 | K28: 2.1 | L28: 2.16 | M28: 2.21 | O28: Derived from FY26 new restaurant capex of $13.8m (p.9) spread across Australian and German openings, escalated for build cost inflation.
C29: New restaurant capex — Germany | D29: A$m/store | E29: 2.2 | F29: 2.25 | G29: 2.3 | H29: 2.35 | I29: 2.4 | J29: 2.46 | K29: 2.52 | L29: 2.58 | M29: 2.65 | O29: Higher than Australia. FY27 German capex is guided at approximately $20m for around 7 new restaurants plus pipeline development (p.33).
C30: New restaurant capex — Netherlands | D30: A$m/store | E30: 2 | F30: 2.05 | G30: 2.1 | H30: 2.15 | I30: 2.2 | J30: 2.26 | K30: 2.31 | L30: 2.37 | M30: 2.43 | O30: Assumed between the Australian and German build cost. Not separately disclosed.
C31: Net working capital as % of revenue | D31: % | E31: -0.06 | F31: -0.06 | G31: -0.06 | H31: -0.06 | I31: -0.06 | J31: -0.06 | K31: -0.06 | L31: -0.06 | M31: -0.06 | O31: NEGATIVE by design: quick service restaurants collect cash instantly and pay suppliers on terms, so growth releases cash. REFINE THIS from the FY26 Annual Report receivables, inventory and payables notes — the results presentation does not give the detail.
C32: Effective tax rate | D32: % | E32: 0.3 | F32: 0.3 | G32: 0.3 | H32: 0.3 | I32: 0.3 | J32: 0.3 | K32: 0.3 | L32: 0.3 | M32: 0.3 | O32: Australian statutory rate. The FY26 underlying effective rate was 29.9% ($26.2m tax on $87.7m profit before tax, p.8), so the statutory rate is a fair proxy despite Dutch and German earnings.
C33: TERMINAL ASSUMPTIONS
C34: Terminal growth rate | D34: % | E34: 0.025 | O34: Long-run nominal growth. The RBA target band midpoint is 2.5%, so this assumes no real growth in perpetuity — appropriate for a mature franchisee operating in defined territories.
C35: Terminal exit EV/EBITDA multiple | D35: x | E35: 7 | O35: Applied to terminal year EBITDA on the active lease basis. CKF currently trades on roughly 6.8x FY26 pre-AASB 16 EBITDA. Populate the Comps sheet to sharpen this.
C38: UPSIDE CASE
C39: Driver | D39: Unit | E39: FY27E | F39: FY28E | G39: FY29E | H39: FY30E | I39: FY31E | J39: FY32E | K39: FY33E | L39: FY34E | M39: FY35E | O39: Basis and source
C40: KFC AUSTRALIA
C41: Net new restaurants | D41: no. | E41: 10 | F41: 10 | G41: 10 | H41: 10 | I41: 10 | J41: 9 | K41: 8 | L41: 7 | M41: 6
C42: Same store sales growth | D42: % | E42: 0.04 | F42: 0.035 | G42: 0.0325 | H42: 0.03 | I42: 0.03 | J42: 0.03 | K42: 0.03 | L42: 0.028 | M42: 0.028
C43: Kwench incremental sales uplift | D43: % | E43: 0.025 | F43: 0.015 | G43: 0.005 | H43: 0 | I43: 0 | J43: 0 | K43: 0 | L43: 0 | M43: 0
C44: Restaurant-level EBITDA margin | D44: % | E44: 0.213 | F44: 0.215 | G44: 0.216 | H44: 0.217 | I44: 0.218 | J44: 0.218 | K44: 0.218 | L44: 0.218 | M44: 0.218
C45: Segment G&A as % of revenue | D45: % | E45: 0.0192 | F45: 0.019 | G45: 0.0188 | H45: 0.0185 | I45: 0.0185 | J45: 0.0185 | K45: 0.0185 | L45: 0.0185 | M45: 0.0185
...

Sheet Historicals
B2: REPORTED HISTORICALS
B4: Line item | D4: Unit | E4: FY23A | F4: FY24A | G4: FY25A | H4: FY26A | I4: Source
B5: Group
C6: Revenue | D6: A$m | G6: 1466.5 | H6: 1592.6 | I6: FY26 presentations
C7: Underlying EBITDA (post-AASB 16) | D7: A$m | G7: 230.1 | H7: 244.5 | I7: FY26 presentations
C8: Underlying EBITDA (pre-AASB 16) | D8: A$m | G8: 154.8 | H8: 160.8 | I8: FY26 presentations
C9: Underlying EBIT (post-AASB 16) | D9: A$m | G9: 118.7 | H9: 130.7 | I9: FY26 presentations
C10: Underlying EBIT (pre-AASB 16) | D10: A$m | G10: 99.3 | H10: 105.3 | I10: FY26 presentations
C11: Underlying NPAT (post-AASB 16) | D11: A$m | G11: 54.4 | H11: 61.4 | I11: FY26 presentations
C12: Underlying NPAT (pre-AASB 16) | D12: A$m | G12: 62.1 | H12: 66.3 | I12: FY26 presentations
C13: Statutory NPAT | D13: A$m | G13: 12.4 | H13: 47.1 | I13: FY26 presentations
C14: Underlying D&A | D14: A$m | G14: 111.3 | H14: 113.9 | I14: FY26 presentations
C15: Underlying net interest | D15: A$m | G15: 39.3 | H15: 43 | I15: FY26 presentations
C16: Basic EPS underlying (cents) | D16: cents | G16: 46.1 | H16: 52 | I16: FY26 presentations
B18: KFC Australia
C19: Restaurants at year end | D19: no. | G19: 288 | H19: 295 | I19: FY26 presentations
C20: Revenue | D20: A$m | E20: 1051.3 | F20: 1121 | G20: 1154.2 | H20: 1241.3 | I20: FY26 presentations
C21: Same store sales growth | D21: % | G21: 0.003 | H21: 0.027 | I21: FY26 presentations
C22: Restaurant-level EBITDA | D22: A$m | G22: 245.2 | H22: 260.5 | I22: FY26 presentations
C23: Restaurant-level EBITDA margin | D23: % | G23: 0.212 | H23: 0.21 | I23: FY26 presentations
C24: Segment EBITDA (post-AASB 16) | D24: A$m | E24: 201.6 | F24: 221.4 | G24: 222.6 | H24: 237.1 | I24: FY26 presentations
C25: Segment EBIT (post-AASB 16) | D25: A$m | E25: 136.1 | F25: 149.7 | G25: 146.2 | H25: 155.8 | I25: FY26 presentations
B27: KFC EUROPE (Germany and the Netherlands)
C28: Restaurants at year end | D28: no. | G28: 78 | H28: 80 | I28: FY26 presentations
C29: of which Germany | D29: no. | G29: 16 | H29: 17 | I29: FY26 presentations
C30: of which the Netherlands | D30: no. | G30: 62 | H30: 63 | I30: FY26 presentations
C31: Revenue | D31: A$m | E31: 248.7 | F31: 313.5 | G31: 312.3 | H31: 351.3 | I31: FY26 presentations
C32: Restaurant-level EBITDA | D32: A$m | G32: 61.9 | H32: 67.8 | I32: FY26 presentations
C33: Restaurant-level EBITDA margin | D33: % | G33: 0.198 | H33: 0.193 | I33: FY26 presentations
C34: Segment EBITDA (post-AASB 16) | D34: A$m | E34: 32.8 | F34: 42.5 | G34: 39.4 | H34: 44.9 | I34: FY26 presentations
C35: Segment EBIT (post-AASB 16) | D35: A$m | E35: 9.2 | F35: 12.1 | G35: 7.6 | H35: 14.9 | I35: FY26 presentations
C36: Germany same store sales growth | D36: % | G36: -0.033 | H36: 0.037 | I36: FY26 presentations
C37: Netherlands same store sales growth | D37: % | G37: -0.025 | H37: 0
B39: GERMANY / NETHERLANDS REVENUE SPLIT — SOLVED, NOT ESTIMATED
C40: Netherlands revenue growth (reported, AUD) | D40: % | H40: 0.116 | I40: Directors report in annual report
C41: Germany revenue growth (reported, AUD) | D41: % | H41: 0.158 | I41: Directors report in annual report
C42: Netherlands revenue — FY25 (solved) | D42: A$m | G42: =(H31-G31*(1+H41))/((1+H40)-(1+H41)) -> 246.27143 | I42: Solves NL + DE = Europe FY25 and NL x 1.116 + DE x 1.158 = Europe FY26 simultaneously
C43: Germany revenue — FY25 (solved) | D43: A$m | G43: =G31-G42 -> 66.028571
C44: Netherlands revenue — FY26 | D44: A$m | H44: =G42*(1+H40) -> 274.83891
C45: Germany revenue — FY26 | D45: A$m | H45: =G43*(1+H41) -> 76.461086
...

Sheet Model
B2: Operating Model
C4: A$ millions unless stated | E4: FY26A | F4: FY27E | G4: FY28E | H4: FY29E | I4: FY30E | J4: FY31E | K4: FY32E | L4: FY33E | M4: FY34E | N4: FY35E | P4: Logic and reasoning
C5: KFC Australia | D5: Units
C6: Restaurants - Opening | D6: no. | E6: =Historicals!G19 -> 288 | F6: =E8 -> 295 | G6: =F8 -> 301 | H6: =G8 -> 307 | I6: =H8 -> 313 | J6: =I8 -> 319 | K6: =J8 -> 325 | L6: =K8 -> 330 | M6: =L8 -> 334 | N6: =M8 -> 337
C7: Net new restaurants | D7: no. | E7: =Historicals!H19-Historicals!G19 -> 7 | F7: =Assumptions!E107 -> 6 | G7: =Assumptions!F107 -> 6 | H7: =Assumptions!G107 -> 6 | I7: =Assumptions!H107 -> 6 | J7: =Assumptions!I107 -> 6 | K7: =Assumptions!J107 -> 5 | L7: =Assumptions!K107 -> 4 | M7: =Assumptions!L107 -> 3 | N7: =Assumptions!M107 -> 3 | P7: FY26 is the reported movement from 288 to 295. Forecast years come from the live assumption block.
C8: Restaurants - Closing | D8: no. | E8: =SUM(E6:E7) -> 295 | F8: =SUM(F6:F7) -> 301 | G8: =SUM(G6:G7) -> 307 | H8: =SUM(H6:H7) -> 313 | I8: =SUM(I6:I7) -> 319 | J8: =SUM(J6:J7) -> 325 | K8: =SUM(K6:K7) -> 330 | L8: =SUM(L6:L7) -> 334 | ... N8: =SUM(N6:N7) -> 340
C9: Avg restaurant trading | D9: no. | E9: =AVERAGE(E8,E6) -> 291.5 | F9: =AVERAGE(F8,F6) -> 298 | G9: =AVERAGE(G8,G6) -> 304 | H9: =AVERAGE(H8,H6) -> 310 | I9: =AVERAGE(I8,I6) -> 316 | J9: =AVERAGE(J8,J6) -> 322 | K9: =AVERAGE(K8,K6) -> 327.5 | L9: =AVERAGE(L8,L6) -> 332 | ... N9: =AVERAGE(N8,N6) -> 338.5 | P9: Average of opening and closing. Revenue is earned across the year, not at the closing count — using closing store numbers overstates revenue in any rollout year.
C10: Avg unit volume (AUV) | D10: A$m | E10: =Historicals!H20/Model!E9 -> 4.258319 | F10: =E10*(1+Assumptions!E108+Assumptions!E109*IF(Control!$D$8=1,1,0)) -> 4.4073602 | G10: =F10*(1+Assumptions!F108+Assumptions!F109*IF(Control!$D$8=1,1,0)) -> 4.5175442 | H10: =G10*(1+Assumptions!G108+Assumptions!G109*IF(Control!$D$8=1,1,0)) -> 4.6078951 | I10: =H10*(1+Assumptions!H108+Assumptions!H109*IF(Control!$D$8=1,1,0)) -> 4.700053 | J10: =I10*(1+Assumptions!I108+Assumptions!I109*IF(Control!$D$8=1,1,0)) -> 4.7940541 | K10: =J10*(1+Assumptions!J108+Assumptions!J109*IF(Control!$D$8=1,1,0)) -> 4.8899351 | L10: =K10*(1+Assumptions!K108+Assumptions!K109*IF(Control!$D$8=1,1,0)) -> 4.9877338 | M10: =L10*(1+Assumptions!L108+Assumptions!L109*IF(Control!$D$8=1,1,0)) -> 5.0874885 | N10: =M10*(1+Assumptions!M108+Assumptions!M109*IF(Control!$D$8=1,1,0)) -> 5.1892383 | P10: FY26 AUV is reported revenue over average restaurants. Grown by same store sales plus the Kwench uplift, which can be switched off on Control to isolate what that single initiative is worth. This line drives roughly 78% of group revenue.
C11: 53rd week adjustment | D11: A$m | E11: 0 | F11: =-E10*E9/53 -> -23.420755 | P11: FY26 was a 53-week year and FY27 reverts to 52. One week of Australian trading is removed from FY27 — a real headwind that headline growth rates hide.
C12: Revenue | D12: A$m | E12: =E9*E10+E11 -> 1241.3 | F12: =F9*F10+F11 -> 1289.9726 | G12: =G9*G10+G11 -> 1373.3334 | H12: =H9*H10+H11 -> 1428.4475 | I12: =I9*I10+I11 -> 1485.2167 | J12: =J9*J10+J11 -> 1543.6854 | K12: =K9*K10+K11 -> 1601.4538 | L12: =L9*L10+L11 -> 1655.9276 | ... N12: =N9*N10+N11 -> 1756.5572
C13: Restaurant-level EBITDA | D13: A$m | E13: =Historicals!H22 -> 260.5 | F13: =F12*Assumptions!E110 -> 265.73435 | G13: =G12*Assumptions!F110 -> 281.53336 | H13: =H12*Assumptions!G110 -> 291.40329 | I13: =I12*Assumptions!H110 -> 302.98422 | J13: =J12*Assumptions!I110 -> 314.91182 | K13: =K12*Assumptions!J110 -> 326.69657 | L13: =L12*Assumptions!K110 -> 337.80924 | M13: =M12*Assumptions!L110 -> 348.19789 | N13: =N12*Assumptions!M110 -> 358.33766
C14: Segment G&A | D14: A$m | E14: =-(Historicals!H22-Historicals!H24) -> -23.4 | F14: =-F12*Assumptions!E111 -> -25.799452 | G14: =-G12*Assumptions!F111 -> -27.466669 | H14: =-H12*Assumptions!G111 -> -28.28326 | I14: =-I12*Assumptions!H111 -> -29.407292 | J14: =-J12*Assumptions!I111 -> -30.564971 | K14: =-K12*Assumptions!J111 -> -31.708784 | L14: =-L12*Assumptions!K111 -> -32.787367 | M14: =-M12*Assumptions!L111 -> -33.795677 | N14: =-N12*Assumptions!M111 -> -34.779832
C15: Segment EBITDA (Post-AASB16) | D15: A$m | E15: =SUM(E13:E14) -> 237.1 | F15: =SUM(F13:F14) -> 239.9349 | G15: =SUM(G13:G14) -> 254.06669 | H15: =SUM(H13:H14) -> 263.12003 | I15: =SUM(I13:I14) -> 273.57692 | J15: =SUM(J13:J14) -> 284.34685 | K15: =SUM(K13:K14) -> 294.98778 | L15: =SUM(L13:L14) -> 305.02187 | ... N15: =SUM(N13:N14) -> 323.55783
C17: KFC Germany
C18: Restaurants - Opening | D18: no. | E18: =Historicals!G29 -> 16 | F18: =E20 -> 17 | G18: =F20 -> 28 | H18: =G20 -> 33 | I18: =H20 -> 38 | J18: =I20 -> 43 | K18: =J20 -> 48 | L18: =K20 -> 52 | M18: =L20 -> 55 | N18: =M20 -> 57
C19: Net new restaurants | D19: no. | E19: =Historicals!H29-Historicals!G29 -> 1 | F19: =Assumptions!E113 -> 11 | G19: =Assumptions!F113 -> 5 | H19: =Assumptions!G113 -> 5 | I19: =Assumptions!H113 -> 5 | J19: =Assumptions!I113 -> 5 | K19: =Assumptions!J113 -> 4 | L19: =Assumptions!K113 -> 3 | M19: =Assumptions!L113 -> 2 | N19: =Assumptions!M113 -> 2 | P19: FY27 includes the 8-restaurant Munich acquisition, which completed 1 June 2026 — after the 3 May 2026 year end, so it lands in FY27 rather than FY26.
C20: Restaurants - Closing | D20: no. | E20: =E18+E19 -> 17 | F20: =F18+F19 -> 28 | G20: =G18+G19 -> 33 | H20: =H18+H19 -> 38 | I20: =I18+I19 -> 43 | J20: =J18+J19 -> 48 | K20: =K18+K19 -> 52 | L20: =L18+L19 -> 55 | ... N20: =N18+N19 -> 59
C21: Avg restaurant trading | D21: no. | E21: =AVERAGE(E20,E18) -> 16.5 | F21: =AVERAGE(F20,F18) -> 22.5 | G21: =AVERAGE(G20,G18) -> 30.5 | H21: =AVERAGE(H20,H18) -> 35.5 | I21: =AVERAGE(I20,I18) -> 40.5 | J21: =AVERAGE(J20,J18) -> 45.5 | K21: =AVERAGE(K20,K18) -> 50 | L21: =AVERAGE(L20,L18) -> 53.5 | ... N21: =AVERAGE(N20,N18) -> 58
C22: Avg unit volume (AUV) | D22: A$m | E22: =Historicals!H45/Model!E21 -> 4.6340052 | F22: =E22*(1+Assumptions!E115) -> 4.4023049 | G22: =F22*(1+Assumptions!F115) -> 4.4023049 | H22: =G22*(1+Assumptions!G115) -> 4.446328 | I22: =H22*(1+Assumptions!H115) -> 4.5130229 | J22: =I22*(1+Assumptions!I115) -> 4.5807182 | K22: =J22*(1+Assumptions!J115) -> 4.649429 | L22: =K22*(1+Assumptions!K115) -> 4.7191705 | M22: =L22*(1+Assumptions!L115) -> 4.789958 | N22: =M22*(1+Assumptions!M115) -> 4.8618074 | P22: SOLVED, not estimated. CKF reports Europe as one segment, but the Annual Report discloses Netherlands revenue growth of 11.6% and German growth of 15.8%. Two equations, two unknowns — see the derivation block on the Historicals sheet.
C23: Revenue | D23: A$m | E23: =E22*E21 -> 76.461086 | F23: =F22*F21 -> 99.051861 | G23: =G22*G21 -> 134.2703 | H23: =H22*H21 -> 157.84464 | I23: =I22*I21 -> 182.77743 | J23: =J22*J21 -> 208.42268 | K23: =K22*K21 -> 232.47145 | L23: =L22*L21 -> 252.47562 | ... N23: =N22*N21 -> 281.98483
C25: KFC Netherlands
C26: Restaurants - Opening | D26: no. | E26: =Historicals!G30 -> 62 | F26: =E28 -> 63 | G26: =F28 -> 63 | H26: =G28 -> 63 | I26: =H28 -> 63 | J26: =I28 -> 63 | K26: =J28 -> 63 | L26: =K28 -> 63 | M26: =L28 -> 63 | N26: =M28 -> 63
C27: Net new restaurants | D27: no. | E27: =Historicals!H30-Historicals!G30 -> 1 | F27: =Assumptions!E117 -> 0 | G27: =Assumptions!F117 -> 0 | H27: =Assumptions!G117 -> 0 | I27: =Assumptions!H117 -> 0 | J27: =Assumptions!I117 -> 0 | K27: =Assumptions!J117 -> 0 | L27: =Assumptions!K117 -> 0 | M27: =Assumptions!L117 -> 0 | N27: =Assumptions!M117 -> 0
C28: Restaurants - Closing | D28: no. | E28: =E26+E27 -> 63 | F28: =F26+F27 -> 63 | G28: =G26+G27 -> 63 | H28: =H26+H27 -> 63 | I28: =I26+I27 -> 63 | J28: =J26+J27 -> 63 | K28: =K26+K27 -> 63 | L28: =L26+L27 -> 63 | ... N28: =N26+N27 -> 63
C29: Avg restaurant trading | D29: no. | E29: =AVERAGE(E28,E26) -> 62.5 | F29: =AVERAGE(F28,F26) -> 63 | G29: =AVERAGE(G28,G26) -> 63 | H29: =AVERAGE(H28,H26) -> 63 | I29: =AVERAGE(I28,I26) -> 63 | J29: =AVERAGE(J28,J26) -> 63 | K29: =AVERAGE(K28,K26) -> 63 | L29: =AVERAGE(L28,L26) -> 63 | ... N29: =AVERAGE(N28,N26) -> 63
C30: Avg unit volume (AUV) | D30: A$m | E30: =Historicals!H44/Model!E29 -> 4.3974226 | F30: =E30*(1+Assumptions!E118) -> 4.1775515 | G30: =F30*(1+Assumptions!F118) -> 4.135776 | H30: =G30*(1+Assumptions!G118) -> 4.1564549 | I30: =H30*(1+Assumptions!H118) -> 4.1980194 | J30: =I30*(1+Assumptions!I118) -> 4.2399996 | K30: =J30*(1+Assumptions!J118) -> 4.2823996 | L30: =K30*(1+Assumptions!K118) -> 4.3252236 | M30: =L30*(1+Assumptions!L118) -> 4.3684758 | N30: =M30*(1+Assumptions!M118) -> 4.4121606 | P30: From the same solved split. Because both countries are now derived independently rather than one being a plug, the Europe total becomes a genuine cross-check rather than an identity — see the check row on Historicals.
C31: Revenue | D31: A$m | E31: =E30*E29 -> 274.83891 | F31: =F30*F29 -> 263.18574 | G31: =G30*G29 -> 260.55389 | H31: =H30*H29 -> 261.85666 | I31: =I30*I29 -> 264.47522 | J31: =J30*J29 -> 267.11998 | K31: =K30*K29 -> 269.79117 | L31: =L30*L29 -> 272.48909 | ... N31: =N30*N29 -> 277.96612
C33: KFC Europe
C34: Revenue | D34: A$m | E34: =E23+E31 -> 351.3 | F34: =F23+F31 -> 362.23761 | G34: =G23+G31 -> 394.82419 | H34: =H23+H31 -> 419.7013 | I34: =I23+I31 -> 447.25265 | J34: =J23+J31 -> 475.54266 | K34: =K23+K31 -> 502.26263 | L34: =L23+L31 -> 524.96471 | ... N34: =N23+N31 -> 559.95095
C35: Restaurant-level EBITDA | D35: A$m | E35: =E34*Historicals!H33 -> 67.8009 | F35: =F34*Assumptions!E120 -> 67.013957 | G35: =G34*Assumptions!F120 -> 73.042475 | H35: =H34*Assumptions!G120 -> 77.64474 | I35: =I34*Assumptions!H120 -> 82.74174 | J35: =J34*Assumptions!I120 -> 87.975391 | K35: =K34*Assumptions!J120 -> 92.918586 | L35: =L34*Assumptions!K120 -> 97.118471 | M35: =M34*Assumptions!L120 -> 100.53855 | N35: =N34*Assumptions!M120 -> 103.59092
C36: Segment G&A | D36: A$m | E36: =-(Historicals!H32-Historicals!H34) -> -22.9 | F36: =-F34*Assumptions!E121 -> -25.71887 | G36: =-G34*Assumptions!F121 -> -27.637693 | H36: =-H34*Assumptions!G121 -> -28.95939 | I36: =-I34*Assumptions!H121 -> -30.41318 | J36: =-J34*Assumptions!I121 -> -32.336901 | K36: =-K34*Assumptions!J121 -> -33.651596 | L36: =-L34*Assumptions!K121 -> -35.172635 | M36: =-M34*Assumptions!L121 -> -36.411259 | N36: =-N34*Assumptions!M121 -> -37.516713
C37: Segment EBITDA (Post-AASB16) | D37: A$m | E37: =SUM(E35:E36) -> 44.9009 | F37: =SUM(F35:F36) -> 41.295087 | G37: =SUM(G35:G36) -> 45.404782 | H37: =SUM(H35:H36) -> 48.685351 | I37: =SUM(I35:I36) -> 52.32856 | J37: =SUM(J35:J36) -> 55.638491 | K37: =SUM(K35:K36) -> 59.26699 | L37: =SUM(L35:L36) -> 61.945835 | ... N37: =SUM(N35:N36) -> 66.074212
C39: GROUP PROFIT & LOSS
C40: Total Revenue | D40: A$m | E40: =E12+E34 -> 1592.6 | F40: =F12+F34 -> 1652.2102 | G40: =G12+G34 -> 1768.1576 | H40: =H12+H34 -> 1848.1488 | I40: =I12+I34 -> 1932.4694 | J40: =J12+J34 -> 2019.2281 | K40: =K12+K34 -> 2103.7164 | L40: =L12+L34 -> 2180.8923 | ... N40: =N12+N34 -> 2316.5081
C41: Revenue Growth | D41: % | E41: =E40/Historicals!G6-1 -> 0.085987044 | F41: =F40/E40-1 -> 0.037429481 | G41: =G40/F40-1 -> 0.07017717 | H41: =H40/G40-1 -> 0.045239831 | I41: =I40/H40-1 -> 0.045624367 | J41: =J40/I40-1 -> 0.044895233 | K41: =K40/J40-1 -> 0.041841892 | L41: =L40/K40-1 -> 0.036685533 | M41: =M40/L40-1 -> 0.031827194 | N41: =N40/M40-1 -> 0.029420061
C42: Segment EBITDA - Australia | D42: A$m | E42: =E15 -> 237.1 | F42: =F15 -> 239.9349 | G42: =G15 -> 254.06669 | H42: =H15 -> 263.12003 | I42: =I15 -> 273.57692 | J42: =J15 -> 284.34685 | K42: =K15 -> 294.98778 | L42: =L15 -> 305.02187 | ... N42: =N15 -> 323.55783
C43: Segment EBITDA - Europe | D43: A$m | E43: =E37 -> 44.9009 | F43: =F37 -> 41.295087 | G43: =G37 -> 45.404782 | H43: =H37 -> 48.685351 | I43: =I37 -> 52.32856 | J43: =J37 -> 55.638491 | K43: =K37 -> 59.26699 | L43: =L37 -> 61.945835 | ... N43: =N37 -> 66.074212
C44: Unallocated corporate cost | D44: A$m | E44: =-(Historicals!H24+Historicals!H34-Historicals!H7) -> -37.5 | F44: =-F40*Assumptions!E123 -> -39.653045 | G44: =-G40*Assumptions!F123 -> -42.435783 | H44: =-H40*Assumptions!G123 -> -44.355571 | I44: =-I40*Assumptions!H123 -> -46.379266 | J44: =-J40*Assumptions!I123 -> -48.461473 | K44: =-K40*Assumptions!J123 -> -50.489193 | L44: =-L40*Assumptions!K123 -> -52.341416 | M44: =-M40*Assumptions!L123 -> -54.007297 | N44: =-N40*Assumptions!M123 -> -55.596195 | P44: Not disclosed as a segment. Derived as the gap between the sum of the two segment EBITDAs and reported group EBITDA.
C45: EBITDA (Post-AASB16) | D45: A$m | E45: =SUM(E42:E44) -> 244.5009 | F45: =SUM(F42:F44) -> 241.57694 | G45: =SUM(G42:G44) -> 257.03568 | H45: =SUM(H42:H44) -> 267.44981 | I45: =SUM(I42:I44) -> 279.52622 | J45: =SUM(J42:J44) -> 291.52387 | K45: =SUM(K42:K44) -> 303.76558 | L45: =SUM(L42:L44) -> 314.62629 | ... N45: =SUM(N42:N44) -> 334.03585
C46: EBITDA Margin (Post-AASB16) | D46: % | E46: =E45/E40 -> 0.15352311 | F46: =F45/F40 -> 0.14621441 | G46: =G45/G40 -> 0.14536921 | H46: =H45/H40 -> 0.14471227 | I46: =I45/I40 -> 0.14464716 | J46: =J45/J40 -> 0.14437392 | K46: =K45/K40 -> 0.14439474 | L46: =L45/L40 -> 0.14426493 | ... N46: =N45/N40 -> 0.144198
...

Sheet Capex & PPE
B2: CAPITAL EXPENDITURE AND FIXED ASSETS
C3: Depreciation is built as a vintage waterfall: each year's capex is split by asset class and depreciated over the useful lives disclosed in Note G5 of the FY26 Annual Report.
C5: A$ millions | D5: Unit | E5: FY26A | F5: FY27E | G5: FY28E | H5: FY29E | I5: FY30E | J5: FY31E | K5: FY32E | L5: FY33E | M5: FY34E | N5: FY35E | P5: Logic and source
C6: ASSET LIVES — PER NOTE G5, FY26 ANNUAL REPORT
C7: Leasehold improvements — useful life | D7: years | E7: 15 | P7: FY26 Annual Report, Note G5 Property, plant and equipment. All classes are straight line. Note G5 specifies '20 years or term of the lease' for building leasehold improvements and 'primary term of lease' for other leasehold improvements. 15 years is used as the effective life because most QSR primary lease terms run 10-15 years, below the 20-year cap. Change this cell if you can source the actual weighted average lease term from Note G8.
C8: Plant and equipment — useful life | D8: years | E8: 8 | P8: FY26 Annual Report, Note G5 Property, plant and equipment. All classes are straight line. Disclosed as 8 years.
C9: Motor vehicles — useful life (memo) | D9: years | E9: 4 | P9: FY26 Annual Report, Note G5 Property, plant and equipment. All classes are straight line. Disclosed as 4 years. Immaterial for a restaurant operator, so not modelled as a separate class.
C10: Capex mix — leasehold improvements | D10: % | E10: 0.55 | P10: ASSUMPTION, not disclosed. Note G5 gives the lives but not how capex splits between classes. A KFC build is weighted toward fitout, drive-thru works and shopfront (leasehold improvements) over kitchen equipment (plant and equipment). 55/45 assumed.
C11: Capex mix — plant and equipment | D11: % | E11: =1-E10 -> 0.45
C12: Blended annual depreciation rate on new capex | D12: % | E12: =E10/E7+E11/E8 -> 0.092916667 | P12: Straight-line rate applied to GROSS cost of each vintage — the correct denominator, unlike a rate struck on net book value.
C13: Implied blended useful life of new capex | D13: years | E13: =1/E12 -> 10.762332
C14: Half-year convention in year of addition | D14: 0 / 1 | E14: 1 | P14: 1 charges half a year of depreciation in the year an asset is bought, which is the standard simplification for assets acquired evenly through the year. Set to 0 for a full year.
C16: CAPITAL EXPENDITURE BY CATEGORY
C17: New restaurants | D17: A$m | E17: =-Model!E59 -> 13.8 | F17: =-Model!F59 -> 18.6 | G17: =-Model!G59 -> 23.95 | H17: =-Model!H59 -> 24.5 | I17: =-Model!I59 -> 25.05 | J17: =-Model!J59 -> 25.6 | K17: =-Model!K59 -> 21.43 | L17: =-Model!L59 -> 17.03 | ... N17: =-Model!N59 -> 12.7
C18: Maintenance and remodels | D18: A$m | E18: =-Model!E58 -> 38.1 | F18: =-Model!F58 -> 33.044204 | G18: =-Model!G58 -> 38.899468 | H18: =-Model!H58 -> 42.507422 | I18: =-Model!I58 -> 44.446796 | J18: =-Model!J58 -> 46.442245 | K18: =-Model!K58 -> 48.385477 | L18: =-Model!L58 -> 50.160524 | ... N18: =-Model!N58 -> 53.279686
C19: Project capex (Kwench) | D19: A$m | E19: =-Model!E60 -> 0 | F19: =-Model!F60 -> 35 | G19: =-Model!G60 -> 12 | H19: =-Model!H60 -> 0 | I19: =-Model!I60 -> 0 | J19: =-Model!J60 -> 0 | K19: =-Model!K60 -> 0 | L19: =-Model!L60 -> 0 | ... N19: =-Model!N60 -> 0
C20: PP&E acquired with the Munich business | D20: A$m | E20: =-Model!E65 -> 0 | F20: 20 | G20: =-Model!G65 -> 0 | H20: =-Model!H65 -> 0 | I20: =-Model!I65 -> 0 | J20: =-Model!J65 -> 0 | K20: =-Model!K65 -> 0 | L20: =-Model!L65 -> 0 | M20: =-Model!M65 -> 0 | N20: =-Model!N65 -> 0 | P20: ESTIMATE — the PP&E slice of the $50.6m consideration, not the whole price. The rest is goodwill, franchise rights and leases. CKF's own purchase price allocation is provisional until HY27. Acquired assets are fair-valued on acquisition so they are depreciated as a fresh vintage.
C21: Total additions | D21: A$m | E21: =SUM(E17:E20) -> 51.9 | F21: =SUM(F17:F20) -> 106.6442 | G21: =SUM(G17:G20) -> 74.849468 | H21: =SUM(H17:H20) -> 67.007422 | I21: =SUM(I17:I20) -> 69.496796 | J21: =SUM(J17:J20) -> 72.042245 | K21: =SUM(K17:K20) -> 69.815477 | L21: =SUM(L17:L20) -> 67.190524 | ... N21: =SUM(N17:N20) -> 65.979686
C23: DEPRECIATION WATERFALL
C24: Each vintage of capex is depreciated over its own life. The legacy pool runs off separately, because those assets are already part-way through theirs.
C25: Legacy pool — opening net book value | D25: A$m | F25: =E45 -> 238.8 | G25: =F28 -> 186.9 | H25: =G28 -> 146.27977 | I25: =H28 -> 114.48781 | J25: =I28 -> 89.605411 | K25: =J28 -> 70.130868 | L25: =K28 -> 54.888858 | M25: =L28 -> 42.959496 | N25: =M28 -> 33.622821
C26: Legacy pool — run-off rate | D26: % | E26: =-E38/E45 -> 0.21733668 | P26: FY26 depreciation divided by FY26 closing net book value. Applied on a declining balance, which models a pool of mixed vintages running off smoothly rather than every legacy asset expiring on the same day. That avoids an artificial cliff in the terminal year.
C27: Legacy pool — depreciation | D27: A$m | F27: =-F25*$E$26 -> -51.9 | G27: =-G25*$E$26 -> -40.620226 | H27: =-H25*$E$26 -> -31.791961 | I27: =-I25*$E$26 -> -24.882402 | J27: =-J25*$E$26 -> -19.474543 | K27: =-K25*$E$26 -> -15.24201 | L27: =-L25*$E$26 -> -11.929362 | M27: =-M25*$E$26 -> -9.3366743 | N27: =-N25*$E$26 -> -7.3074725
C28: Legacy pool — closing net book value | D28: A$m | F28: =F25+F27 -> 186.9 | G28: =G25+G27 -> 146.27977 | H28: =H25+H27 -> 114.48781 | I28: =I25+I27 -> 89.605411 | J28: =J25+J27 -> 70.130868 | K28: =K25+K27 -> 54.888858 | L28: =L25+L27 -> 42.959496 | M28: =M25+M27 -> 33.622821 | N28: =N25+N27 -> 26.315349
C29: FY27E capex vintage — depreciation | D29: A$m | F29: =-F21*$E$12*IF($E$14=1,0.5,1) -> -4.954512 | G29: =-$F21*$E$12 -> -9.9090239 | H29: =-$F21*$E$12 -> -9.9090239 | I29: =-$F21*$E$12 -> -9.9090239 | J29: =-$F21*$E$12 -> -9.9090239 | K29: =-$F21*$E$12 -> -9.9090239 | L29: =-$F21*$E$12 -> -9.9090239 | M29: =-$F21*$E$12 -> -9.9090239 | N29: =-$F21*$E$12 -> -9.9090239
C30: FY28E capex vintage — depreciation | D30: A$m | F30: 0 | G30: =-G21*$E$12*IF($E$14=1,0.5,1) -> -3.4773815 | H30: =-$G21*$E$12 -> -6.9547631 | I30: =-$G21*$E$12 -> -6.9547631 | J30: =-$G21*$E$12 -> -6.9547631 | K30: =-$G21*$E$12 -> -6.9547631 | L30: =-$G21*$E$12 -> -6.9547631 | M30: =-$G21*$E$12 -> -6.9547631 | N30: =-$G21*$E$12 -> -6.9547631
C31: FY29E capex vintage — depreciation | D31: A$m | F31: 0 | G31: 0 | H31: =-H21*$E$12*IF($E$14=1,0.5,1) -> -3.1130531 | I31: =-$H21*$E$12 -> -6.2261063 | J31: =-$H21*$E$12 -> -6.2261063 | K31: =-$H21*$E$12 -> -6.2261063 | L31: =-$H21*$E$12 -> -6.2261063 | M31: =-$H21*$E$12 -> -6.2261063 | N31: =-$H21*$E$12 -> -6.2261063
C32: FY30E capex vintage — depreciation | D32: A$m | F32: 0 | G32: 0 | H32: 0 | I32: =-I21*$E$12*IF($E$14=1,0.5,1) -> -3.2287053 | J32: =-$I21*$E$12 -> -6.4574106 | K32: =-$I21*$E$12 -> -6.4574106 | L32: =-$I21*$E$12 -> -6.4574106 | M32: =-$I21*$E$12 -> -6.4574106 | N32: =-$I21*$E$12 -> -6.4574106
C33: FY31E capex vintage — depreciation | D33: A$m | F33: 0 | G33: 0 | H33: 0 | I33: 0 | J33: =-J21*$E$12*IF($E$14=1,0.5,1) -> -3.3469627 | K33: =-$J21*$E$12 -> -6.6939253 | L33: =-$J21*$E$12 -> -6.6939253 | M33: =-$J21*$E$12 -> -6.6939253 | N33: =-$J21*$E$12 -> -6.6939253
C34: FY32E capex vintage — depreciation | D34: A$m | F34: 0 | G34: 0 | H34: 0 | I34: 0 | J34: 0 | K34: =-K21*$E$12*IF($E$14=1,0.5,1) -> -3.2435107 | L34: =-$K21*$E$12 -> -6.4870214 | M34: =-$K21*$E$12 -> -6.4870214 | N34: =-$K21*$E$12 -> -6.4870214
C35: FY33E capex vintage — depreciation | D35: A$m | F35: 0 | G35: 0 | H35: 0 | I35: 0 | J35: 0 | K35: 0 | L35: =-L21*$E$12*IF($E$14=1,0.5,1) -> -3.1215598 | M35: =-$L21*$E$12 -> -6.2431195 | N35: =-$L21*$E$12 -> -6.2431195
C36: FY34E capex vintage — depreciation | D36: A$m | F36: 0 | G36: 0 | H36: 0 | I36: 0 | J36: 0 | K36: 0 | L36: 0 | M36: =-M21*$E$12*IF($E$14=1,0.5,1) -> -2.9796978 | N36: =-M21*$E$12 -> -5.9593956
C37: FY35E capex vintage — depreciation | D37: A$m | F37: 0 | G37: 0 | H37: 0 | I37: 0 | J37: 0 | K37: 0 | L37: 0 | M37: 0 | N37: =-N21*$E$12*IF($E$14=1,0.5,1) -> -3.0653063
C38: Total depreciation | D38: A$m | E38: =-(Historicals!H14-Historicals!H67+E48) -> -51.9 | F38: =F27+SUM(F29:F37) -> -56.854512 | G38: =G27+SUM(G29:G37) -> -54.006632 | H38: =H27+SUM(H29:H37) -> -51.768801 | I38: =I27+SUM(I29:I37) -> -51.201 | J38: =J27+SUM(J29:J37) -> -52.36881 | K38: =K27+SUM(K29:K37) -> -54.72675 | L38: =L27+SUM(L29:L37) -> -57.779173 | M38: =M27+SUM(M29:M37) -> -61.287742 | N38: =N27+SUM(N29:N37) -> -65.303544 | P38: FY26 is derived from reported figures: total D&A less right-of-use depreciation less intangible amortisation. Forecast years are the legacy run-off plus each vintage.
C40: PROPERTY, PLANT AND EQUIPMENT ROLL-FORWARD
C41: Opening PP&E | D41: A$m | E41: 247.4 | F41: =E45 -> 238.8 | G41: =F45 -> 288.58969 | H41: =G45 -> 309.43253 | I41: =H45 -> 324.67115 | J41: =I45 -> 342.96694 | K41: =J45 -> 362.64038 | L41: =K45 -> 377.72911 | M41: =L45 -> 387.14046 | N41: =M45 -> 389.98971 | P41: FY25 closing PP&E, FY26 presentation p.10 balance sheet
C42: Additions | D42: A$m | E42: =E21 -> 51.9 | F42: =F21 -> 106.6442 | G42: =G21 -> 74.849468 | H42: =H21 -> 67.007422 | I42: =I21 -> 69.496796 | J42: =J21 -> 72.042245 | K42: =K21 -> 69.815477 | L42: =L21 -> 67.190524 | ... N42: =N21 -> 65.979686
C43: Depreciation | D43: A$m | E43: =E38 -> -51.9 | F43: =F38 -> -56.854512 | G43: =G38 -> -54.006632 | H43: =H38 -> -51.768801 | I43: =I38 -> -51.201 | J43: =J38 -> -52.36881 | K43: =K38 -> -54.72675 | L43: =L38 -> -57.779173 | ... N43: =N38 -> -65.303544
C44: Disposals, impairment and FX | D44: A$m | F44: 0 | G44: 0 | H44: 0 | I44: 0 | J44: 0 | K44: 0 | L44: 0 | M44: 0 | N44: 0 | P44: FY26 is the balancing figure (net impairments of $6.5m, the land parcel sale and FX). Forecast at zero because impairments are non-trading by definition — state that rather than letting it look like an oversight.
C45: Closing PP&E | D45: A$m | E45: 238.8 | F45: =F41+F42+F43+F44 -> 288.58969 | G45: =G41+G42+G43+G44 -> 309.43253 | H45: =H41+H42+H43+H44 -> 324.67115 | I45: =I41+I42+I43+I44 -> 342.96694 | J45: =J41+J42+J43+J44 -> 362.64038 | K45: =K41+K42+K43+K44 -> 377.72911 | L45: =L41+L42+L43+L44 -> 387.14046 | M45: =M41+M42+M43+M44 -> 389.98971 | N45: =N41+N42+N43+N44 -> 390.66585 | P45: FY26 closing PP&E per presentation p.10, hardcoded so the disposals line solves as the balancer
...

Sheet Debt & Leases
B2: DEBT, LEASES AND COVENANT CAPACITY
C5: A$ millions | D5: Unit | E5: FY26A | F5: FY27E | G5: FY28E | H5: FY29E | I5: FY30E | J5: FY31E | K5: FY32E | L5: FY33E | M5: FY34E | N5: FY35E | P5: Logic and source
C6: FINANCING ASSUMPTIONS
C7: Interest rate on drawn debt | E7: 0.056 | P7: Consistent with the cost of debt on the WACC sheet.
C8: Interest rate earned on cash | E8: 0.035 | P8: Assumption — Australian at-call deposit rates.
C9: Dividend payout ratio | E9: 0.538 | P9: FY26 actual: 28.0 cents declared against underlying EPS of 52.0 cents.
C10: Minimum operating cash balance | E10: 60 | P10: Assumption. CKF held $93.9m at FY26; a QSR needs far less than that as float.
C11: Covenant: maximum net leverage | E11: 3 | P11: NOT DISCLOSED in the material I could access. 3.0x is typical for an Australian corporate syndicated facility.
C13: GROSS DEBT SCHEDULE
C14: Opening gross debt | D14: A$m | E14: =Historicals!G52 -> 257 | F14: =E17 -> 213.5 | G14: =F17 -> 226.20175 | H14: =G17 -> 207.06797 | I14: =H17 -> 181.4636 | J14: =I17 -> 155.81388 | K14: =J17 -> 129.18269 | L14: =K17 -> 96.129509 | M14: =L17 -> 56.270702 | N14: =M17 -> 8.9506937
C15: Drawdown to fund acquisitions | D15: A$m | E15: 0 | F15: =-Model!F65 -> 50.6 | G15: =-Model!G65 -> 0 | H15: =-Model!H65 -> 0 | I15: =-Model!I65 -> 0 | J15: =-Model!J65 -> 0 | K15: =-Model!K65 -> 0 | L15: =-Model!L65 -> 0 | M15: =-Model!M65 -> 0 | N15: =-Model!N65 -> 0 | P15: The Munich acquisition was 'funded from existing finance facilities' per the Annual Report, so it draws debt rather than consuming cash.
C16: Repayment from surplus cash flow | D16: A$m | E16: =Historicals!H52-'Debt & Leases'!E14 -> -43.5 | F16: =-MIN(MAX(0,F27-$E$10),F14+F15) -> -37.898254 | G16: =-MIN(MAX(0,G27-$E$10),G14+G15) -> -19.133777 | H16: =-MIN(MAX(0,H27-$E$10),H14+H15) -> -25.604373 | I16: =-MIN(MAX(0,I27-$E$10),I14+I15) -> -25.64972 | J16: =-MIN(MAX(0,J27-$E$10),J14+J15) -> -26.631191 | K16: =-MIN(MAX(0,K27-$E$10),K14+K15) -> -33.053177 | L16: =-MIN(MAX(0,L27-$E$10),L14+L15) -> -39.858808 | M16: =-MIN(MAX(0,M27-$E$10),M14+M15) -> -47.320008 | N16: =-MIN(MAX(0,N27-$E$10),N14+N15) -> -8.9506937 | P16: Cash sweep: any cash above the minimum operating balance repays debt, capped at the amount outstanding. This is a policy assumption, not a contractual one.
C17: Closing gross debt | D17: A$m | E17: =SUM(E14:E16) -> 213.5 | F17: =F14+F15+F16 -> 226.20175 | G17: =G14+G15+G16 -> 207.06797 | H17: =H14+H15+H16 -> 181.4636 | I17: =I14+I15+I16 -> 155.81388 | J17: =J14+J15+J16 -> 129.18269 | K17: =K14+K15+K16 -> 96.129509 | L17: =L14+L15+L16 -> 56.270702 | M17: =M14+M15+M16 -> 8.9506937 | N17: =N14+N15+N16 -> 0
C19: CASH FLOW WATERFALL
C20: Opening cash | D20: A$m | E20: =Historicals!G51 -> 119.1 | F20: =E28 -> 93.9 | G20: =F28 -> 60 | H20: =G28 -> 60 | I20: =H28 -> 60 | J20: =I28 -> 60 | K20: =J28 -> 60 | L20: =K28 -> 60 | M20: =L28 -> 60 | N20: =M28 -> 60
C21: Unlevered free cash flow (FCFF) | D21: A$m | E21: =Model!E79 -> 77.352626 | F21: =Model!F79 -> -8.9774219 | G21: =Model!G79 -> 61.52468 | H21: =Model!H79 -> 70.362315 | I21: =Model!I79 -> 72.530921 | J21: =Model!J79 -> 74.864666 | K21: =Model!K79 -> 82.275773 | L21: =Model!L79 -> 89.291796 | ... N21: =Model!N79 -> 98.911251 | P21: Already net of capex, working capital and the acquisition
C22: Less: interest on debt | D22: A$m | E22: -12.1 | F22: =-F14*$E$7 -> -11.956 | G22: =-G14*$E$7 -> -12.667298 | H22: =-H14*$E$7 -> -11.595806 | I22: =-I14*$E$7 -> -10.161961 | J22: =-J14*$E$7 -> -8.7255771 | K22: =-K14*$E$7 -> -7.2342304 | L22: =-L14*$E$7 -> -5.3832525 | M22: =-M14*$E$7 -> -3.1511593 | N22: =-N14*$E$7 -> -0.50123885 | P22: Charged on the OPENING balance, deliberately. Using the average balance would make interest depend on the repayment, which depends on cash flow, which depends on interest — a circular reference. Banks resolve that with iterative calculation; a template that has to survive being emailed around should not rely on it.
C23: Add: interest earned on cash | D23: A$m | E23: 4 | F23: =F20*$E$8 -> 3.2865 | G23: =G20*$E$8 -> 2.1 | H23: =H20*$E$8 -> 2.1 | I23: =I20*$E$8 -> 2.1 | J23: =J20*$E$8 -> 2.1 | K23: =K20*$E$8 -> 2.1 | L23: =L20*$E$8 -> 2.1 | M23: =M20*$E$8 -> 2.1 | N23: =N20*$E$8 -> 2.1
C24: Add: tax shield on net interest | D24: A$m | E24: =-(E22+E23)*Historicals!$H$65 -> 2.4290764 | F24: =-(F22+F23)*Historicals!$H$65 -> 2.5998615 | G24: =-(G22+G23)*Historicals!$H$65 -> 3.1689844 | H24: =-(H22+H23)*Historicals!$H$65 -> 2.8476591 | I24: =-(I22+I23)*Historicals!$H$65 -> 2.4176692 | J24: =-(J22+J23)*Historicals!$H$65 -> 1.9869177 | K24: =-(K22+K23)*Historicals!$H$65 -> 1.5396837 | L24: =-(L22+L23)*Historicals!$H$65 -> 0.98460138 | ... N24: =-(N22+N23)*Historicals!$H$65 -> -0.47944605 | P24: FCFF was struck after tax on the FULL EBIT, so the tax saved on interest has to be handed back here. This is the other side of the rule that the tax shield belongs in the WACC, not in FCFF.
C25: Memo: NPAT | D25: A$m | E25: =(Model!E55+'Debt & Leases'!E22+'Debt & Leases'!E23)*(1-Historicals!$H$65) -> 67.981702 | F25: =(Model!F55+F22+F23)*(1-Historicals!$H$65) -> 58.651833 | G25: =(Model!G55+G22+G23)*(1-Historicals!$H$65) -> 65.041989 | H25: =(Model!H55+H22+H23)*(1-Historicals!$H$65) -> 70.836051 | I25: =(Model!I55+I22+I23)*(1-Historicals!$H$65) -> 76.648531 | J25: =(Model!J55+J22+J23)*(1-Historicals!$H$65) -> 81.031256 | K25: =(Model!K55+K22+K23)*(1-Historicals!$H$65) -> 84.810502 | L25: =(Model!L55+L22+L23)*(1-Historicals!$H$65) -> 87.610292 | M25: =(Model!M55+M22+M23)*(1-Historicals!$H$65) -> 89.92922 | N25: =(Model!N55+N22+N23)*(1-Historicals!$H$65) -> 91.989335
C26: Less: dividends paid | D26: A$m | E26: -31.1 | F26: =-F25*$E$9 -> -31.554686 | G26: =-G25*$E$9 -> -34.99259 | H26: =-H25*$E$9 -> -38.109795 | I26: =-I25*$E$9 -> -41.23691 | J26: =-J25*$E$9 -> -43.594815 | K26: =-K25*$E$9 -> -45.62805 | L26: =-L25*$E$9 -> -47.134337 | M26: =-M25*$E$9 -> -48.38192 | N26: =-N25*$E$9 -> -49.490262
C27: Cash before debt movements | D27: A$m | E27: =E20+E21+E22+E23+E24+E26+E15 -> 159.6817 | F27: =F20+F21+F22+F23+F24+F26+F15 -> 97.898254 | G27: =G20+G21+G22+G23+G24+G26+G15 -> 79.133777 | H27: =H20+H21+H22+H23+H24+H26+H15 -> 85.604373 | I27: =I20+I21+I22+I23+I24+I26+I15 -> 85.64972 | J27: =J20+J21+J22+J23+J24+J26+J15 -> 86.631191 | K27: =K20+K21+K22+K23+K24+K26+K15 -> 93.053177 | L27: =L20+L21+L22+L23+L24+L26+L15 -> 99.858808 | ... N27: =N20+N21+N22+N23+N24+N26+N15 -> 110.5403 | P27: The FY26A column anchors opening and closing balances to reported figures; it is NOT a full cash reconciliation of the actual year, because the modelled FCFF differs from reported operating cash flow on working capital timing. The waterfall operates from FY27 onward.
C28: Closing cash | D28: A$m | E28: =Historicals!H51 -> 93.9 | F28: =F27+F16 -> 60 | G28: =G27+G16 -> 60 | H28: =H27+H16 -> 60 | I28: =I27+I16 -> 60 | J28: =J27+J16 -> 60 | K28: =K27+K16 -> 60 | L28: =L27+L16 -> 60 | M28: =M27+M16 -> 60 | N28: =N27+N16 -> 101.58961
C30: NET DEBT AND COVENANT HEADROOM
C31: Closing net debt (excluding leases) | D31: A$m | E31: =E17-E28 -> 119.6 | F31: =F17-F28 -> 166.20175 | G31: =G17-G28 -> 147.06797 | H31: =H17-H28 -> 121.4636 | I31: =I17-I28 -> 95.813877 | J31: =J17-J28 -> 69.182686 | K31: =K17-K28 -> 36.129509 | L31: =L17-L28 -> -3.7292983 | ... N31: =N17-N28 -> -101.58961
C32: EBITDA (pre-AASB 16, covenant basis) | D32: A$m | E32: =Model!E48 -> 160.8009 | F32: =Model!F48 -> 153.1837 | G32: =Model!G48 -> 161.55517 | H32: =Model!H48 -> 166.7257 | I32: =Model!I48 -> 173.2404 | J32: =Model!J48 -> 179.45671 | K32: =Model!K48 -> 185.95746 | L32: =Model!L48 -> 191.40587 | ... N32: =Model!N48 -> 200.83663
C33: Net leverage ratio | D33: x | E33: =IFERROR(E31/E32,0) -> 0.74377693 | F33: =IFERROR(F31/F32,0) -> 1.0849832 | G33: =IFERROR(G31/G32,0) -> 0.91032659 | H33: =IFERROR(H31/H32,0) -> 0.72852355 | I33: =IFERROR(I31/I32,0) -> 0.55306889 | J33: =IFERROR(J31/J32,0) -> 0.38551183 | K33: =IFERROR(K31/K32,0) -> 0.19428911 | L33: =IFERROR(L31/L32,0) -> -0.019483719 | ... N33: =IFERROR(N31/N32,0) -> -0.50583208 | P33: FY26A reads 0.74x against the 0.77x CKF reports on p.10 — and the gap is instructive rather than an error. Solving back, the covenant EBITDA is about $155m, which is continuing-operations EBITDA of $160.8m LESS the $5.6m pre-AASB 16 Taco Bell loss. In other words the covenant is struck on total group earnings including discontinued operations, while this row uses continuing operations.
C34: Covenant headroom | D34: x | E34: =$E$11-E33 -> 2.2562231 | F34: =$E$11-F33 -> 1.9150168 | G34: =$E$11-G33 -> 2.0896734 | H34: =$E$11-H33 -> 2.2714764 | I34: =$E$11-I33 -> 2.4469311 | J34: =$E$11-J33 -> 2.6144882 | K34: =$E$11-K33 -> 2.8057109 | L34: =$E$11-L33 -> 3.0194837 | ... N34: =$E$11-N33 -> 3.5058321
C35: Additional debt capacity at the covenant limit | D35: A$m | E35: =E32*$E$11-E31 -> 362.8027 | F35: =F32*$E$11-F31 -> 293.34935 | G35: =G32*$E$11-G31 -> 337.59755 | H35: =H32*$E$11-H31 -> 378.7135 | I35: =I32*$E$11-I31 -> 423.90733 | J35: =J32*$E$11-J31 -> 469.18745 | K35: =K32*$E$11-K31 -> 521.74287 | L35: =L32*$E$11-L31 -> 577.94692 | ... N35: =N32*$E$11-N31 -> 704.0995 | P35: The number an acquirer or a board asks for first: how much more could this balance sheet borrow before it breaches? It also frames whether CKF could fund further German bolt-ons without equity.
C36: Interest cover (EBITDA / net interest) | D36: x | E36: =IFERROR(-E32/(E22+E23),0) -> 19.851963 | F36: =IFERROR(-F32/(F22+F23),0) -> 17.669266 | G36: =IFERROR(-G32/(G22+G23),0) -> 15.28822 | H36: =IFERROR(-H32/(H22+H23),0) -> 17.557824 | I36: =IFERROR(-I32/(I22+I23),0) -> 21.488617 | J36: =IFERROR(-J32/(J22+J23),0) -> 27.085446 | K36: =IFERROR(-K32/(K22+K23),0) -> 36.21915 | L36: =IFERROR(-L32/(L22+L23),0) -> 58.29764 | ... N36: =IFERROR(-N32/(N22+N23),0) -> -125.62016
C38: LEASE LIABILITY ROLL-FORWARD (memo)
C39: Opening lease liability | D39: A$m | E39: =Historicals!G54 -> 633.6 | F39: =E42 -> 630.5 | G39: =F42 -> 654.09929 | H39: =G42 -> 700.00212 | I39: =H42 -> 731.6701 | J39: =I42 -> 765.05209 | K39: =J42 -> 799.39928 | L39: =K42 -> 832.84766 | M39: =L42 -> 863.40112 | N39: =M42 -> 890.88075
C40: New and renewed leases | D40: A$m | E40: =E42-E39-E41 -> 54.8 | F40: =F42-F39-F41 -> 83.666455 | G40: =G42-G39-G41 -> 110.18535 | H40: =H42-H39-H41 -> 98.858618 | I40: =I42-I39-I41 -> 103.63816 | J40: =J42-J39-J41 -> 107.75753 | K40: =K42-K39-K41 -> 109.93034 | L40: =L42-L39-L41 -> 109.84121 | ... N40: =N42-N39-N41 -> 110.42791 | P40: Signing a lease is a financing event, not a cash outflow — an asset and a liability appear together. That is exactly why leased restaurants look free in a post-AASB 16 cash flow.
C41: Principal repayments | D41: A$m | E41: =-Historicals!H59 -> -57.9 | F41: =E41*(1+Model!F41) -> -60.067167 | G41: =F41*(1+Model!G41) -> -64.282511 | H41: =G41*(1+Model!H41) -> -67.190641 | I41: =H41*(1+Model!I41) -> -70.256171 | J41: =I41*(1+Model!J41) -> -73.410338 | K41: =J41*(1+Model!K41) -> -76.481966 | L41: =K41*(1+Model!L41) -> -79.287747 | M41: =L41*(1+Model!M41) -> -81.811254 | N41: =M41*(1+Model!N41) -> -84.218146
C42: Closing lease liability | D42: A$m | E42: =Historicals!H54 -> 630.5 | F42: =F39*(1+Model!F41) -> 654.09929 | G42: =G39*(1+Model!G41) -> 700.00212 | H42: =H39*(1+Model!H41) -> 731.6701 | I42: =I39*(1+Model!I41) -> 765.05209 | J42: =J39*(1+Model!J41) -> 799.39928 | K42: =K39*(1+Model!K41) -> 832.84766 | L42: =L39*(1+Model!L41) -> 863.40112 | M42: =M39*(1+Model!M41) -> 890.88075 | N42: =N39*(1+Model!N41) -> 917.09052
C43: Lease-adjusted leverage ((net debt + leases) / post-AASB 16 EBITDA) | D43: x | E43: =IFERROR((E31+E42)/Model!E45,0) -> 3.0678824 | F43: =IFERROR((F31+F42)/Model!F45,0) -> 3.3956098 | G43: =IFERROR((G31+G42)/Model!G45,0) -> 3.295535 | H43: =IFERROR((H31+H42)/Model!H45,0) -> 3.1898834 | I43: =IFERROR((I31+I42)/Model!I45,0) -> 3.0797324 | J43: =IFERROR((J31+J42)/Model!J45,0) -> 2.979454 | K43: =IFERROR((K31+K42)/Model!K45,0) -> 2.8606835 | L43: =IFERROR((L31+L42)/Model!L45,0) -> 2.7323585 | ... N43: =IFERROR((N31+N42)/Model!N45,0) -> 2.4413575 | P43: The covenant says 0.77x. Capitalise the leases and the same company is around 3x. Neither number is wrong — they answer different questions. Knowing both, and knowing why they differ, is the point.

Sheet WACC
B2: WEIGHTED AVERAGE COST OF CAPITAL
C3: Two WACCs are computed. The capital structure MUST match the cash flow definition: leases are debt only when rent has been added back to EBITDA.
C5: MARKET INPUTS
C6: Risk free rate | E6: 0.049 | K6: Australian 10-year Commonwealth Government bond yield, approximately 4.9% in early August 2026.
C7: Market risk premium | E7: 0.06 | K7: 6.0% is the figure most commonly adopted in Australian independent expert reports. It is an assumption.
C8: Corporate tax rate | E8: 0.3 | K8: Australian statutory rate. FY26 underlying effective rate was 29.9%.
C10: BETA — UNLEVER THE COMPARABLES, THEN RELEVER FOR CKF
C11: Comparable company | E11: Equity beta | F11: Net debt / equity | G11: Tax rate | H11: Unlevered beta
C12: Domino's Pizza Enterprises (ASX:DMP) | E12: 1.02 | F12: 0.39 | G12: 0.3 | H12: =IFERROR(E12/(1+(1-G12)*F12),"") -> 0.80125687 | K12: Net debt is from FY25 as FY26 results are not out yet. Will be updated as and when available
C13: Guzman y Gomez (ASX:GYG) | E13: 0.91 | F13: 0.05 | G13: 0.3 | H13: =IFERROR(E13/(1+(1-G13)*F13),"") -> 0.87922705
C14: Arcos Dorados (NYSE:ARCO) | E14: 0.5 | F14: 1.16 | G14: 0.3 | H14: =IFERROR(E14/(1+(1-G14)*F14),"") -> 0.27593819
C15: Yum! Brands (NYSE:YUM) | E15: 0.55 | F15: 0.32 | G15: 0.21 | H15: =IFERROR(E15/(1+(1-G15)*F15),"") -> 0.4390166
C16: Yum China (NYSE:YUMC) | E16: 0.08 | F16: 0.055 | G16: 0.25 | H16: =IFERROR(E16/(1+(1-G16)*F16),"") -> 0.076830732
C17: Median unlevered beta of the comparables | H17: =IFERROR(MEDIAN(H12:H16),"n/a") -> 0.4390166
C18: Selected unlevered (asset) beta | E18: 0.8 | K18: Using 0.80 here as it is close to asx listed dominos and GyG. Damodarans unlevered beta for restaurant in US is 0.77.
C20: CAPITAL STRUCTURE AT MARKET VALUE
C21: Share price (A$) | E21: 8.24 | K21: Closing price early August 2026. Update to your valuation date.
C22: Shares on issue (m) | E22: =Historicals!H11/(Historicals!H16/100) -> 118.07692 | K22: Derived: underlying NPAT divided by reported basic EPS. Cross-check against the share count in the Annual Report — this gives the weighted average, not the closing count.
C23: Market capitalisation (A$m) | E23: =E21*E22 -> 972.95385
C24: Net debt excluding leases (A$m) | E24: =Historicals!H53 -> 119.6
C25: Lease liabilities (A$m) | E25: =Historicals!H54 -> 630.5
C26: Debt used in the WACC | E26: =E24 -> 119.6 | K26: Lease liabilities are deliberately EXCLUDED, because the cash flows still carry rent as an operating cost. Including them here while also expensing rent would penalise the same obligation twice.
C27: Debt / (debt + equity) | E27: =E26/(E26+E23) -> 0.10946829
C28: Debt / equity | E28: =E26/E23 -> 0.12292464
C30: COST OF EQUITY
C31: Relevered equity beta | E31: =E18*(1+(1-E8)*E28) -> 0.8688378 | K31: Hamada relevering. Note the beta is materially higher on a post-AASB 16 basis — capitalising leases makes the equity look more levered, which is economically correct.
C32: Cost of equity | E32: =E6+E31*E7 -> 0.10113027 | K32: CAPM: risk free rate plus beta times market risk premium.
C34: COST OF DEBT
C35: Cost of corporate debt (pre-tax) | E35: 0.056 | K35: Approximately BBSW plus a corporate margin. CKF refinanced during FY26; the facility margin is in the Annual Report debt note — replace this placeholder with the actual margin.
C36: Cost of lease debt (pre-tax) | E36: =Historicals!H70 -> 0.051259964 | K36: The incremental borrowing rate implied by CKF's own lease accounting — lease interest over the average lease liability.
C37: Pre-tax cost of debt used | E37: =E35 -> 0.056
C38: After-tax cost of debt | E38: =E37*(1-E8) -> 0.0392
C40: WACC
C41: WACC | E41: =E32*(1-E27)+E38*E27 -> 0.094350867
C43: MEMO: WHAT A LEASE-ADJUSTED CAPITAL STRUCTURE WOULD LOOK LIKE | K43: Not used in the valuation — here to helo answer the question
C44: Gearing including lease liabilities | E44: =(E24+E25)/(E24+E25+E23) -> 0.43533172
C45: Relevered beta on that basis | E45: =E18*(1+(1-E8)*(E24+E25)/E23) -> 1.2317327
C46: Lease-adjusted net leverage (net debt + leases / post-AASB 16 EBITDA) | E46: =(E24+E25)/Historicals!H7 -> 3.0678937 | K46: CKF reports net leverage of 0.77x on a pre-AASB 16 covenant basis. Capitalising leases tells a very different story about how levered this business really is — worth raising yourself.
C48: A caveat worth knowing:
C49: The comparables' observed equity betas already embed their own lease obligations, so unlevering them on financial debt alone is a simplification. Raise it before someone raises it for you.

Sheet DCF
B2: DISCOUNTED CASH FLOW
